File: HC/HC_Cavendish_CrCl2pym-Ag_2to60K.dat
[Header]
TITLE,20201208_CrCl2pym-Ag_HC_2to60K.dat
BYAPP,HeatCapacity,3.9.6,1.7
INFO,4.4,MASS:Sample Mass (mg)
INFO,0.2,MASSERR:Sample Mass Error (mg)
INFO,0,MOLWGHT:Formula Weight (g/mole)
INFO,0,ATOMS:Atoms per Formula Unit
INFO,PPMS Heat Capacity Option 3.9.6 Build 3,APPNAME
DATATYPE,TIME,1
DATATYPE,COMMENT,2
STARTUPAXIS, X, 8, LINEAR, AUTO
STARTUPAXIS, Y1, 10, LINEAR, AUTO
[Data]
Time Stamp (Seconds),Comment (),System Status (Code),Puck Temp (Kelvin),System Temp (Kelvin),Field (Oersted),Pressure (Torr),Sample Temp (Kelvin),Temp Rise (Kelvin),Samp HC (muJ/K),Samp HC Err (muJ/K),Addenda HC (muJ/K),Addenda HC Err (muJ/K),Total HC (muJ/K),Total HC Err (muJ/K),Fit Deviation (ChiSquare),Time Const tau1 (seconds),Time Const tau2 (seconds),Sample Coupling (Percent),Debye Temp (Kelvin),Debye Temp Err (Kelvin),Cal Correction (Factor),Therm Resist (Ohms),Htr Resist (Ohms),Puck Resist (Ohms),Wire Cond (W/K),Meas Time (seconds),Temp Squared (K^2),Samp HC/Temp (muJ/K/K),Addenda Offset HC (muJ/K)
3816569673.13442,CALFILE: C:\QDDYNA~1\HEATCA~1\TempCal\Standard\Puck1810.cal|Addenda #127 measured on 26/11/2020 from 1.8431 to 60.449 K
3816569673.13676,,1857,1.79999,1.79999,-0.15407714,9.8999999E-6,1.8195271,0.036902066,4.1974589,0.07482,0.35840197,0.0007675,4.5558609,0.07482,777.9867,2.5377586,,,,,1,,,,1.7952302E-6,5.0730242,3.3106788,2.3068955,0
3816569923.97342,,1857,1.9999,1.9999,-0.13037296,9.8999999E-6,2.0189568,0.040879504,4.4787729,0.07198,0.44061871,0.001005,4.9193916,0.07198,257.5004,2.460912,,,,,1,,,,1.9990116E-6,4.9188089,4.0761865,2.2183599,0
3816570188.70515,,1857,2.20008,2.20008,-0.14222506,9.8999999E-6,2.2180315,0.045209293,4.7235516,0.07087,0.54953508,0.00166,5.2730867,0.07085,383.55121,2.4052396,,,,,1,,,,2.1923333E-6,4.8055849,4.9196638,2.1296143,0
3816570524.18572,,1857,2.59993,2.59993,-0.17778131,9.8999999E-6,2.6170326,0.057087777,5.0248965,0.01643,0.55538081,0.001085,5.5802773,0.01643,61.311832,2.5622683,0.010946542,95.077338,,,1,,,,2.2697068E-6,4.5001111,6.8488595,1.9200741,0
3816570769.54478,,1857,2.80008,2.80008,-0.15407714,9.8999999E-6,2.8195859,0.06644116,5.3482126,0.01446,0.63632441,0.001188,5.984537,0.01446,39.997106,2.5135827,0.011375817,95.087897,,,1,,,,2.4795726E-6,5.0196137,7.9500648,1.8968078,0
3816571013.44703,,1857,3.0001,3.0001,-0.11852087,9.8999999E-6,3.0193589,0.069938321,5.6325944,0.01432,0.73946683,0.001386,6.3720612,0.01432,32.906989,2.4319021,0.012051969,95.023919,,,1,,,,2.727965E-6,4.8801446,9.1165281,1.8654935,0
3816571349.45798,,1857,3.40045,3.40045,-0.15407714,9.8999999E-6,3.4198812,0.078005466,6.3365502,0.01599,0.99244362,0.001879,7.3289938,0.01599,45.757794,2.4106451,0.013930093,94.930599,,,1,,,,3.1623572E-6,4.8080501,11.695587,1.8528568,0
3816571593.27848,,1857,3.59968,3.59968,-0.1896334,9.8999999E-6,3.6218995,0.082062782,6.7239948,0.01651,1.1461801,0.002107,7.8701749,0.01651,15.86513,2.3949867,0.01508814,94.805586,,,1,,,,3.4183933E-6,4.8049213,13.118156,1.856483,0
3816571833.61995,,1857,3.80025,3.80025,-0.22518967,9.8999999E-6,3.8219376,0.085650353,7.1566093,0.01735,1.3171863,0.002457,8.4737956,0.01735,5.1050659,2.3924675,0.01620571,94.71334,,,1,,,,3.6838786E-6,4.8145353,14.607207,1.8725081,0
3816572167.48443,,1857,4.20028,4.20028,-0.10666879,9.8999999E-6,4.2222563,0.09231353,8.1548125,0.02072,1.7128629,0.003197,9.8676754,0.02072,12.276119,2.4356643,0.018950378,94.454542,,,1,,,,4.2151004E-6,4.865549,17.827448,1.9313874,0
3816572408.69438,,1857,4.4002,4.4002,-0.11852087,9.8999999E-6,4.4231829,0.096870663,8.7415108,0.02072,1.956079,0.004193,10.69759,0.02072,63.199433,2.4788818,0.02026826,94.413575,,,1,,,,4.4874546E-6,4.9937075,19.564547,1.9762942,0
3816572650.9461,,1857,4.60023,4.60023,-0.16592923,9.8999999E-6,4.6236598,0.10077583,9.3532132,0.02377,2.2178516,0.00492,11.571065,0.02377,25.126813,2.5445121,0.022103562,94.282638,,,1,,,,4.7292822E-6,5.0660429,21.37823,2.0229026,0
3816572985.94902,,1857,5.00029,5.00029,-0.1896334,9.8999999E-6,5.0240975,0.10780081,10.741728,0.02718,2.7745886,0.005598,13.516316,0.02718,30.762493,2.6709513,0.025518705,94.038198,,,1,,,,5.2651492E-6,5.2526378,25.241555,2.1380413,0
3816573229.55677,,1857,5.19966,5.19966,-0.16592923,9.8999999E-6,5.2255516,0.11341253,11.511772,0.02962,3.077537,0.006168,14.589309,0.02962,20.913597,2.7376578,0.027087116,93.953662,,,1,,,,5.5448671E-6,5.4725748,27.30639,2.2029774,0
3816573474.33144,,1857,5.40004,5.40004,-0.14222506,9.8999999E-6,5.426086,0.11701283,12.333223,0.03158,3.3981027,0.006983,15.731326,0.03158,18.61683,2.7951687,0.028526445,93.874809,,,1,,,,5.856174E-6,5.5923553,29.442409,2.2729501,0
3816573812.15965,,1857,5.80005,5.80005,-0.14222506,9.8999999E-6,5.8262132,0.12269302,14.144481,0.0394,4.0906991,0.009207,18.235181,0.0394,15.29869,2.961643,0.032244668,93.646779,,,1,,,,6.4113214E-6,5.742026,33.944761,2.4277315,0
3816574066.55993,,1857,5.99966,5.99966,-0.11852087,9.8999999E-6,6.0289817,0.13038397,15.186565,0.03794,4.466091,0.01051,19.652656,0.03794,24.315931,3.0502956,0.033145823,93.721841,,,1,,,,6.7035362E-6,6.1187969,36.348621,2.5189271,0
3816574319.51182,,1857,6.20011,6.20011,-0.14222506,9.8999999E-6,6.2295619,0.13465787,16.233312,0.04379,4.8629819,0.01195,21.096294,0.04379,16.202608,3.146032,0.035757551,93.499179,,,1,,,,6.985052E-6,6.2863685,38.807441,2.6058513,0
3816574663.93786,,1857,6.59997,6.59997,-0.16592923,9.8999999E-6,6.6314011,0.13953367,18.537376,0.04883,5.7274675,0.0157,24.264844,0.04883,76.073599,3.3158887,0.038555892,93.465056,,,1,,,,7.6200247E-6,6.4401338,43.975481,2.7953936,0
3816574921.48977,,1857,6.79984,6.79984,-0.13037296,9.8999999E-6,6.8338777,0.14739479,19.799899,0.04974,6.1921893,0.01694,25.992088,0.04974,26.047262,3.4137087,0.040218884,93.422903,,,1,,,,7.9289524E-6,6.8225526,46.701885,2.8973153,0
3816575184.81235,,1857,6.99952,6.99952,0.24889384,9.8999999E-6,7.0350223,0.15153054,21.150649,0.05444,6.6771633,0.01671,27.827812,0.05444,22.82228,3.5140211,0.04224806,93.321948,,,1,,,,8.2505952E-6,7.0316674,49.491538,3.0064793,0
3816575540.08215,,1857,7.4001,7.4001,0.27259803,9.8999999E-6,7.4346926,0.15697751,23.975642,0.06327,7.6966683,0.01465,31.67231,0.06327,81.01519,3.7357726,0.046374848,93.166097,,,1,,,,8.8391495E-6,7.2504996,55.274654,3.224833,0
3816575807.31114,,1857,7.60063,7.60063,0.27259803,9.8999999E-6,7.6371757,0.16492063,25.435686,0.07093,8.2454112,0.01445,33.681097,0.07093,37.656941,3.8449112,0.048671912,93.067052,,,1,,,,9.1370609E-6,7.644007,58.326452,3.3305094,0
3816576079.52373,,1857,7.79982,7.79982,0.2963022,9.8999999E-6,7.8386302,0.16908567,26.943392,0.06556,8.8037712,0.015,35.747163,0.06556,57.911321,3.9144038,0.0492407,93.141606,,,1,,,,9.5192984E-6,7.8505781,61.444123,3.4372577,0
3816576442.23902,,1857,8.19998,8.19998,-0.10666879,9.8999999E-6,8.238239,0.17413158,30.207117,0.07836,9.9893341,0.01796,40.196451,0.07836,26.151715,4.1498201,0.053509488,93.013769,,,1,,,,1.0102776E-5,8.0581143,67.868581,3.6666959,0
3816576719.81057,,1857,8.40012,8.40012,-0.17778131,9.8999999E-6,8.4409509,0.18181046,31.938154,0.08421,10.620817,0.01992,42.558971,0.08421,72.773348,4.2489484,0.055496045,92.943781,,,1,,,,1.0450522E-5,8.457984,71.249651,3.7837152,0
3816576999.07308,,1857,8.60023,8.60023,-0.13037296,9.8999999E-6,8.6422053,0.18680363,33.644566,0.08863,11.2628,0.02184,44.907366,0.08863,23.90927,4.3400828,0.057190179,92.906023,,,1,,,,1.079677E-5,8.7224058,74.687713,3.8930533,0
3816577372.17132,,1857,8.99992,8.99992,-0.2963022,9.8999999E-6,9.042185,0.19124931,37.285024,0.09476,12.577296,0.02557,49.86232,0.09476,50.930355,4.5419407,0.060419723,92.867371,,,1,,,,1.145629E-5,8.9298302,81.76111,4.1234529,0
3816577660.44323,,1857,9.1999,9.1999,-0.27259803,9.8999999E-6,9.2456544,0.19997132,39.199665,0.1013,13.2803,0.02758,52.479965,0.1013,52.947146,4.6681984,0.062855363,92.796187,,,1,,,,1.1735875E-5,9.3573047,85.482125,4.2397934,0
3816577949.71337,,1857,9.39978,9.39978,-0.14222506,9.8999999E-6,9.447052,0.20440585,41.110893,0.1085,13.994386,0.02978,55.105279,0.1085,99.07075,4.7605954,0.06459622,92.758321,,,1,,,,1.2085494E-5,9.5825891,89.246791,4.3517166,0
3816578327.2043,,1857,9.79984,9.79984,-0.28445011,9.8999999E-6,9.8478915,0.20830842,45.258553,0.1242,15.483456,0.03533,60.742008,0.1242,45.066877,5.0002397,0.068810413,92.673947,,,1,,,,1.2688725E-5,9.7749396,96.980967,4.5957607,0
3816578624.93373,,1857,9.99972,9.99972,-0.22518967,9.8999999E-6,10.051986,0.2173507,47.46415,0.1286,16.271665,0.0386,63.735815,0.1286,48.448532,5.1005251,0.07027236,92.673477,,,1,,,,1.3051798E-5,10.23928,101.04243,4.7218678,0
3816578925.83087,,1857,10.2002,10.2002,-0.16592923,9.8999999E-6,10.253474,0.22161222,49.68563,0.1359,17.081024,0.04155,66.766654,0.1359,76.768968,5.2095995,0.072430017,92.616834,,,1,,,,1.3390205E-5,10.458412,105.13373,4.8457362,0
3816579312.46758,,1857,10.5996,10.5996,0.21333757,9.8999999E-6,10.653224,0.22537765,54.197607,0.1491,18.747704,0.04445,72.945311,0.1491,46.589937,5.4362824,0.076548257,92.545892,,,1,,,,1.4023768E-5,10.658353,113.49119,5.087437,0
3816579620.02253,,1857,10.8003,10.8003,0.22518967,9.8999999E-6,10.85729,0.23520858,56.73738,0.1527,19.622666,0.04444,76.360046,0.1527,29.34412,5.5561376,0.078117719,92.556587,,,1,,,,1.4362657E-5,11.142583,117.88074,5.2257406,0
3816579933.31322,,1857,10.9995,10.9995,0.23704174,9.8999999E-6,11.058397,0.23878948,59.079796,0.1576,20.512818,0.04409,79.592614,0.1576,77.668988,5.6428131,0.079590648,92.548034,,,1,,,,1.474026E-5,11.323225,122.28815,5.3425279,0
3816580330.93056,,1857,11.4001,11.4001,0.1896334,9.8999999E-6,11.457086,0.24265171,64.10924,0.1753,22.339991,0.04421,86.449231,0.1753,62.701955,5.88326,0.083994438,92.470472,,,1,,,,1.5362075E-5,11.552068,131.26483,5.5955971,0
3816580648.04013,,1857,11.5999,11.5999,0.28445011,9.8999999E-6,11.660636,0.25173714,66.738008,0.1841,23.308091,0.04509,90.046099,0.1841,22.904332,5.9945962,0.085818018,92.458608,,,1,,,,1.5704454E-5,11.965673,135.97043,5.7233592,0
3816580966.80172,,1857,11.8002,11.8002,0.27259803,9.8999999E-6,11.861878,0.25679797,69.472935,0.1864,24.270607,0.04652,93.743542,0.1864,34.704427,6.1111386,0.087242799,92.48112,,,1,,,,1.6035124E-5,12.237657,140.70415,5.8568243,0
3816581376.69778,,1857,12.2005,12.2005,0.2014855,9.8999999E-6,12.260857,0.26082321,74.861193,0.2031,26.256204,0.05115,101.1174,0.2031,71.104901,6.3435091,0.091132797,92.448776,,,1,,,,1.6664807E-5,12.491066,150.32862,6.1057062,0
3816581703.80224,,1857,12.3996,12.3996,0.22518967,9.8999999E-6,12.464823,0.27061907,77.621164,0.2147,27.304383,0.05438,104.92555,0.2147,18.124651,6.4554632,0.093099481,92.431044,,,1,,,,1.699331E-5,12.935271,155.37181,6.2272176,0
3816582035.64063,,1857,12.5997,12.5997,0.16592923,9.8999999E-6,12.665279,0.27420506,80.632767,0.2163,28.33651,0.05796,108.96928,0.2163,10.530449,6.5725705,0.094712449,92.433326,,,1,,,,1.733389E-5,13.109816,160.40928,6.3664424,0
3816582455.31523,,1857,13.0002,13.0002,-0.26074591,9.8999999E-6,13.064542,0.27825088,86.321038,0.2343,30.471663,0.06625,116.7927,0.2343,59.406769,6.8090017,0.099020058,92.381051,,,1,,,,1.7937387E-5,13.356934,170.68225,6.6072765,0
3816582793.14589,,1857,13.2001,13.2001,-0.24889384,9.8999999E-6,13.269402,0.28882803,89.321963,0.2466,31.600951,0.07071,120.92291,0.2466,25.373148,6.9186374,0.10063206,92.388642,,,1,,,,1.8275638E-5,13.85631,176.07703,6.7314235,0
3816583135.3744,,1857,13.3999,13.3999,0.21333757,9.8999999E-6,13.472331,0.29311784,92.347631,0.263,32.735053,0.07482,125.08268,0.263,64.309355,7.0372817,0.10256408,92.38094,,,1,,,,1.8585695E-5,14.067809,181.50369,6.8546143,0
3816583565.54541,,1857,13.8003,13.8003,0.14222506,9.8999999E-6,13.871188,0.2968908,98.566947,0.2681,35.001524,0.08074,133.56847,0.2681,74.495285,7.2845126,0.1065957,92.356926,,,1,,,,1.917513E-5,14.317138,192.40985,7.1058764,0
3816583916.3238,,1857,13.9995,13.9995,0.15407714,9.8999999E-6,14.075826,0.30817524,101.94124,0.2846,36.206928,0.0823,138.14817,0.2846,27.371169,7.4235947,0.1087137,92.351824,,,1,,,,1.9461564E-5,14.848063,198.12887,7.2422921,0
3816584268.86075,,1857,14.1999,14.1999,-0.22518967,9.8999999E-6,14.276833,0.31188984,105.1873,0.2919,37.404897,0.08312,142.59219,0.2919,45.242386,7.5336018,0.11026439,92.360921,,,1,,,,1.9792619E-5,15.023604,203.82797,7.3676911,0
3816584710.88665,,1857,14.6005,14.6005,-0.28445011,9.8999999E-6,14.676151,0.31531625,111.88908,0.3004,39.828634,0.08409,151.71771,0.3004,42.003014,7.7873507,0.11422308,92.348411,,,1,,,,2.0374214E-5,15.302902,215.3894,7.6238707,0
3816585072.11227,,1857,14.8003,14.8003,-0.21333757,9.8999999E-6,14.881034,0.32668527,115.40527,0.3134,41.120045,0.085,156.52531,0.3134,32.281693,7.9055731,0.11598356,92.350546,,,1,,,,2.070476E-5,15.850326,221.44519,7.7551913,0
3816585693.52858,,1857,14.9997,14.9997,-0.21333757,9.8999999E-6,15.089311,0.33162775,118.97846,0.3355,42.452323,0.08658,161.43078,0.3355,14.660385,8.0344207,0.11822113,92.333337,,,1,,,,2.1012803E-5,16.102667,227.6873,7.8849497,0
3816586139.88414,,1857,15.4001,15.4001,-0.23704174,9.8999999E-6,15.4872,0.33316032,126.47536,0.3528,45.039159,0.09139,171.51452,0.3528,35.591865,8.3161146,0.12255034,92.313724,,,1,,,,2.1572747E-5,16.319758,239.85335,8.1664448,0
3816586511.59534,,1857,15.6004,15.6004,-0.17778131,9.8999999E-6,15.69209,0.34451885,130.07564,0.3592,46.417377,0.09477,176.49302,0.3592,13.44424,8.4333416,0.12436386,92.316731,,,1,,,,2.1888912E-5,16.84911,246.24168,8.2892492,0
3816586885.45257,,1857,15.7998,15.7998,-0.14222506,9.8999999E-6,15.893401,0.34837316,134.02297,0.3787,47.784826,0.09862,181.8078,0.3787,22.068071,8.5511769,0.125496,92.350655,,,1,,,,2.2233042E-5,17.084216,252.60019,8.4326176,0
3816587344.38063,,1857,16.2002,16.2002,-0.17778131,9.8999999E-6,16.292008,0.35153547,141.72925,0.391,50.526128,0.1074,192.25538,0.391,19.188259,8.8431731,0.12967615,92.356432,,,1,,,,2.2733595E-5,17.408925,265.42952,8.6993114,0
3816587726.63663,,1857,16.4001,16.4001,-0.17778131,9.8999999E-6,16.49819,0.36274865,145.8443,0.4079,51.986252,0.1122,197.83055,0.4079,19.467477,8.9596062,0.13144042,92.352545,,,1,,,,2.3089477E-5,17.943142,272.19026,8.8400186,0
3816588112.88436,,1857,16.5999,16.5999,0.23704174,9.8999999E-6,16.699366,0.36740922,149.86875,0.4146,53.424109,0.1167,203.29286,0.4146,45.323858,9.1058316,0.13365797,92.348598,,,1,,,,2.3346529E-5,18.198371,278.86881,8.9745177,0
3816588592.70945,,1857,16.9995,16.9995,0.2014855,9.8999999E-6,17.097259,0.36867563,158.40528,0.4371,56.291882,0.1239,214.69716,0.4371,217.7134,9.3990156,0.13760148,92.35631,,,1,,,,2.3887639E-5,18.473391,292.31626,9.2649518,0
3816588989.8768,,1857,17.1999,17.1999,-0.23704174,9.8999999E-6,17.302999,0.38083892,162.65924,0.4485,57.817253,0.1265,220.4765,0.4485,32.535258,9.5141488,0.1383305,92.410453,,,1,,,,2.4225432E-5,19.068454,299.39377,9.4006389,0
3816589390.48871,,1857,17.4005,17.4005,0.21333757,9.8999999E-6,17.504118,0.38524304,167.27317,0.4525,59.303032,0.1285,226.5762,0.4525,15.683712,9.6778146,0.14101393,92.383405,,,1,,,,2.4480224E-5,19.355345,306.39416,9.5562179,0
3816589874.27919,,1857,17.8002,17.8002,-0.17778131,9.8999999E-6,17.901776,0.38627098,176.37559,0.4947,62.319406,0.1319,238.695,0.4947,147.87716,9.9972875,0.14524558,92.392264,,,1,,,,2.4965959E-5,19.629303,320.47358,9.8524076,0
3816590284.93999,,1857,17.9997,17.9997,-0.13037296,9.8999999E-6,18.107876,0.39881922,181.1283,0.5043,63.920191,0.1338,245.04849,0.5043,27.91271,10.12407,0.14721201,92.38078,,,1,,,,2.5312057E-5,20.285548,327.89518,10.002736,0
3816590698.85704,,1857,18.2,18.2,-0.15407714,9.8999999E-6,18.309645,0.40269091,186.18194,0.5036,65.480219,0.1362,251.66216,0.5036,14.482281,10.26969,0.1475175,92.460878,,,1,,,,2.5615614E-5,20.548123,335.2431,10.168517,0
3816591197.17594,,1857,18.6006,18.6006,-0.15407714,9.8999999E-6,18.706947,0.40360816,195.90791,0.5472,68.639563,0.1428,264.54747,0.5472,131.76395,10.611642,0.15291837,92.421049,,,1,,,,2.6068211E-5,20.867666,349.94985,10.472469,0
3816591622.59544,,1857,18.8006,18.8006,-0.11852087,9.8999999E-6,18.913596,0.41662749,201.18628,0.5536,70.30073,0.1468,271.48701,0.5536,26.55587,10.75451,0.15375119,92.471113,,,1,,,,2.6389847E-5,21.529594,357.7241,10.637125,0
3816592054.21027,,1857,18.9999,18.9999,-0.15407714,9.8999999E-6,19.114874,0.42065184,206.03246,0.5592,71.94499,0.151,277.97745,0.5592,18.64985,10.89618,0.1560965,92.45268,,,1,,,,2.6672947E-5,21.803003,365.37842,10.778646,0
3816592575.96237,,1857,19.4001,19.4001,-0.14222506,9.8999999E-6,19.5121,0.4219114,215.34421,0.592,75.22578,0.1591,290.56999,0.592,63.108733,11.209342,0.16048936,92.458698,,,1,,,,2.7101046E-5,22.103337,380.72205,11.036445,0
3816593014.10277,,1857,19.6006,19.6006,-0.28445011,9.8999999E-6,19.718559,0.43456379,219.99973,0.5662,76.940336,0.1627,296.94007,0.5662,13.880537,11.314051,0.16108275,92.506045,,,1,,,,2.7429951E-5,22.655155,388.82156,11.156988,0
3816593465.79649,,1857,19.7998,19.7998,-0.2014855,9.8999999E-6,19.919718,0.43909754,224.06641,0.5767,78.635292,0.1659,302.7017,0.5767,7.9316448,11.444101,0.1634414,92.496295,,,1,,,,2.7644003E-5,22.868204,396.79517,11.248473,0
3816593985.0703,,1857,20.1998,20.1998,0.17778131,9.8999999E-6,20.317669,0.44122886,230.43875,0.5699,82.017446,0.1716,312.4562,0.5699,82.68751,11.636354,0.16786,92.475955,,,1,,,,2.8058218E-5,23.013963,412.80769,11.341791,0
3816594430.93332,,1857,20.4004,20.4004,0.2014855,9.8999999E-6,20.524354,0.45350036,233.21885,0.5639,83.804511,0.1745,317.02336,0.5639,5.6265658,11.66962,0.1686492,92.499652,,,1,,,,2.8376948E-5,23.37847,421.24911,11.36303,0
3816594877.28801,,1857,20.5994,20.5994,0.2014855,9.8999999E-6,20.725234,0.45687019,235.57417,0.5627,85.548641,0.1775,321.12281,0.5627,6.7427798,11.703366,0.17082106,92.465502,,,1,,,,2.8660356E-5,23.392302,429.53531,11.366539,0
3816595403.27057,,1857,21.0003,21.0003,0.17778131,9.8999999E-6,21.123484,0.46046403,239.73023,0.5743,89.054311,0.1846,328.78454,0.5743,114.43914,11.841267,0.1755985,92.432213,,,1,,,,2.89936E-5,23.498142,446.20157,11.348991,0
3816595867.70282,,1857,21.2003,21.2003,0.23704174,9.8999999E-6,21.329311,0.47209887,241.90611,0.554,90.878855,0.1891,332.78497,0.554,45.449655,11.852413,0.1764027,92.447568,,,1,,,,2.9308562E-5,23.744146,454.93953,11.341487,0
3816596319.6138,,1857,21.3998,21.3998,0.24889384,9.8999999E-6,21.530722,0.47594035,243.85643,0.548,92.695311,0.1939,336.55174,0.548,7.491796,11.884043,0.17823333,92.433699,,,1,,,,2.9556029E-5,23.747418,463.57201,11.325975,0
3816596862.71974,,1857,21.7996,21.7996,0.27259803,9.8999999E-6,21.928554,0.4787948,247.91564,0.5716,96.328428,0.204,344.24407,0.5716,31.346387,11.997729,0.18288761,92.391576,,,1,,,,2.9937718E-5,23.829016,480.86149,11.305608,0
3816597318.32432,,1857,22.0005,22.0005,0.22518967,9.8999999E-6,22.134752,0.48976813,249.98879,0.565,98.242321,0.2094,348.23111,0.565,5.5336922,11.982705,0.18336063,92.404273,,,1,,,,3.0312219E-5,24.0413,489.94725,11.29395,0
3816597774.18835,,1857,22.1999,22.1999,0.15407714,9.8999999E-6,22.3355,0.49322011,252.44505,0.5768,100.11632,0.2145,352.56137,0.5768,5.9114921,12.043002,0.18524859,92.397773,,,1,,,,3.0530274E-5,24.043415,498.87457,11.302413,0
3816598318.74418,,1857,22.5998,22.5998,0.21333757,9.8999999E-6,22.733657,0.49558908,257.05692,0.5867,103.871,0.2236,360.92792,0.5867,42.818748,12.177269,0.18989297,92.360952,,,1,,,,3.0903512E-5,24.157009,516.81914,11.307328,0
3816598789.61245,,1857,22.7994,22.7994,0.16592923,9.8999999E-6,22.940936,0.50829618,259.3594,0.5841,105.8565,0.2278,365.21589,0.5841,9.0420525,12.175478,0.19069054,92.36371,,,1,,,,3.1267467E-5,24.492074,526.28655,11.305528,0
3816599251.01687,,1857,23.0007,23.0007,0.1896334,9.8999999E-6,23.141739,0.51178298,261.87106,0.5902,107.78607,0.2316,369.65713,0.5902,3.6923263,12.231804,0.19195606,92.378455,,,1,,,,3.1493074E-5,24.518555,535.54006,11.315963,0
3816599790.71604,,1857,23.3994,23.3994,-0.28445011,9.8999999E-6,23.5395,0.51359093,266.6217,0.5859,111.61831,0.2389,378.24001,0.5859,14.395759,12.374243,0.19718507,92.320761,,,1,,,,3.1851401E-5,24.585343,554.10806,11.326566,0
3816600257.71709,,1857,23.5997,23.5997,-0.34371054,9.8999999E-6,23.745888,0.5264233,268.94544,0.5776,113.65002,0.2428,382.59546,0.5776,5.8343445,12.404953,0.19831137,92.328795,,,1,,,,3.212985E-5,24.884447,563.86722,11.325979,0
3816600725.51296,,1857,23.7996,23.7996,-0.33185846,9.8999999E-6,23.947264,0.53002234,270.83298,0.5807,115.63599,0.2468,386.46897,0.5807,4.7552666,12.450006,0.20087155,92.293684,,,1,,,,3.2336327E-5,24.872728,573.47144,11.309559,0
3816601282.5109,,1857,24.1995,24.1995,0.0948167,9.8999999E-6,24.344542,0.53209827,274.73468,0.6018,119.58405,0.2557,394.31873,0.6018,22.687264,12.559257,0.20469278,92.281806,,,1,,,,3.2693389E-5,24.947985,592.65672,11.285268,0
3816601753.43405,,1857,24.4001,24.4001,0.15407714,9.8999999E-6,24.551354,0.54422387,277.19544,0.6067,121.66861,0.2611,398.86405,0.6067,5.6987502,12.582497,0.20545683,92.295711,,,1,,,,3.3000014E-5,25.193682,602.76899,11.290434,0
3816602224.28588,,1857,24.6002,24.6002,0.11852087,9.8999999E-6,24.752796,0.54840588,279.5996,0.6168,123.70349,0.2667,403.30309,0.6168,3.6588051,12.632229,0.20777711,92.266133,,,1,,,,3.3235146E-5,25.270167,612.70091,11.295677,0
3816602799.63994,,1857,24.9999,24.9999,0.15407714,9.8999999E-6,25.152182,0.54971516,285.10579,0.6363,127.76527,0.2785,412.87106,0.6363,45.285251,12.798683,0.21177181,92.262833,,,1,,,,3.3571468E-5,25.408051,632.63226,11.335231,0
3816603275.45877,,1857,25.2006,25.2006,-0.28445011,9.8999999E-6,25.36029,0.56327138,288.18459,0.6306,129.8841,0.2848,418.06868,0.6306,6.6162718,12.827706,0.21267099,92.266469,,,1,,,,3.3911868E-5,25.767543,643.14433,11.363615,0
3816603754.69652,,1857,25.4002,25.4002,-0.2963022,9.8999999E-6,25.56139,0.56722988,291.09321,0.6322,131.95957,0.291,423.05278,0.6322,3.0705686,12.907497,0.21418838,92.278563,,,1,,,,3.4096999E-5,25.845696,653.38466,11.388004,0
3816604328.73674,,1857,25.8004,25.8004,-0.23704174,9.8999999E-6,25.958432,0.56703533,297.35208,0.6688,136.08001,0.303,433.43209,0.6688,21.924371,13.102839,0.21979894,92.225507,,,1,,,,3.4414993E-5,25.945558,673.84021,11.454932,0
3816604837.58315,,1857,25.9997,25.9997,-0.27259803,9.8999999E-6,26.166719,0.58206595,300.40238,0.6728,138.27186,0.3091,438.67424,0.6728,3.8141086,13.148195,0.22034179,92.251983,,,1,,,,3.4701201E-5,26.394464,684.69718,11.480323,0
3816605333.51678,,1857,26.1998,26.1998,-0.27259803,9.8999999E-6,26.368159,0.58587657,303.63802,0.6817,140.3915,0.3147,444.02952,0.6817,2.7977976,13.237656,0.22271987,92.235846,,,1,,,,3.4886761E-5,26.473936,695.27983,11.515329,0
3816605912.97329,,1857,26.6003,26.6003,-0.26074591,9.8999999E-6,26.765704,0.58707524,310.14317,0.6794,144.56973,0.3253,454.7129,0.6794,56.598987,13.444908,0.22682487,92.240798,,,1,,,,3.5167586E-5,26.663049,716.4029,11.587335,0
3816606418.92771,,1857,26.8002,26.8002,-0.28445011,9.8999999E-6,26.973697,0.60100681,313.31044,0.6888,146.7995,0.3306,460.10994,0.6888,41.297486,13.48487,0.22772574,92.249483,,,1,,,,3.5473466E-5,27.04781,727.58033,11.615406,0
3816606941.10165,,1857,27.0005,27.0005,-0.2963022,9.8999999E-6,27.175096,0.60486311,316.61801,0.6918,148.96037,0.3356,465.57838,0.6918,17.522457,13.568265,0.22945999,92.251503,,,1,,,,3.5670529E-5,27.139833,738.48586,11.651035,0
3816607516.31847,,1857,27.3995,27.3995,0.14222506,9.8999999E-6,27.572176,0.60482038,323.63432,0.7283,153.24755,0.3452,476.88187,0.7283,34.554701,13.783148,0.23503553,92.207478,,,1,,,,3.5969886E-5,27.320955,760.2249,11.737714,0
3816608031.23702,,1857,27.6007,27.6007,0.13037296,9.8999999E-6,27.781709,0.61927367,327.20314,0.717,155.51188,0.3501,482.71501,0.717,3.2300564,13.808495,0.23468,92.245154,,,1,,,,3.6332401E-5,27.740079,771.82335,11.777646,0
3816608535.37371,,1857,27.7996,27.7996,0.15407714,9.8999999E-6,27.983255,0.62233415,331.0098,0.7272,157.72104,0.3547,488.73084,0.7272,3.2749608,13.908341,0.23728689,92.223286,,,1,,,,3.6523171E-5,27.812916,783.06255,11.828853,0
3816609122.00253,,1857,28.1999,28.1999,0.0948167,9.8999999E-6,28.380014,0.62135696,338.95865,0.7627,162.09961,0.3637,501.05826,0.7627,17.280789,14.144873,0.24344435,92.16647,,,1,,,,3.6826229E-5,27.999712,805.42521,11.943569,0
3816609628.69526,,1857,28.4003,28.4003,0.071112528,9.8999999E-6,28.589489,0.63676511,343.35461,0.7839,164.44767,0.3684,507.80227,0.7839,2.6849761,14.196405,0.24457391,92.1634,,,1,,,,3.7185674E-5,28.47657,817.35887,12.00982,0
3816610167.45077,,1857,28.6005,28.6005,0.16592923,9.8999999E-6,28.790356,0.64014542,347.57761,0.7854,166.70044,0.3729,514.27805,0.7854,9.6593061,14.298511,0.24586045,92.182743,,,1,,,,3.7385818E-5,28.58345,828.88457,12.07271,0
3816610776.07029,,1857,29.0003,29.0003,0.13037296,9.8999999E-6,29.186818,0.63893588,355.46893,0.7922,171.1456,0.3813,526.61453,0.7922,19.217909,14.501502,0.24992695,92.176784,,,1,,,,3.7744401E-5,28.781087,851.87033,12.179092,0
3816611308.55742,,1857,29.2008,29.2008,0.21333757,9.8999999E-6,29.395628,0.65294793,359.88634,0.806,173.53979,0.3857,533.42614,0.806,2.2922881,14.544898,0.25076361,92.178818,,,1,,,,3.8116698E-5,29.227554,864.10295,12.242853,0
3816611843.97268,,1857,29.3999,29.3999,0.082964614,9.8999999E-6,29.596175,0.65441383,364.33674,0.8224,175.84002,0.3899,540.17676,0.8224,2.3697207,14.622978,0.25258089,92.166953,,,1,,,,3.8394582E-5,29.253354,875.93356,12.310265,0
3816612462.52754,,1857,29.8006,29.8006,0.33185846,9.8999999E-6,29.990815,0.6531307,372.02899,0.853,180.4075,0.3979,552.43648,0.853,13.745682,14.854774,0.25856789,92.121343,,,1,,,,3.8658172E-5,29.436109,899.44896,12.404764,0
3816613017.39156,,1857,29.9999,29.9999,0.26074591,9.8999999E-6,30.199431,0.66697039,376.65572,0.8218,182.82612,0.402,559.48184,0.8218,24.543974,14.874961,0.25787506,92.156035,,,1,,,,3.9089919E-5,29.855715,912.00563,12.472279,0
3816613561.69448,,1857,30.2001,30.2001,0.30815428,9.8999999E-6,30.398852,0.66740126,381.24339,0.8454,185.16807,0.406,566.41146,0.8454,7.6790828,14.946811,0.26019424,92.125522,,,1,,,,3.938964E-5,29.849156,924.09021,12.541375,0
3816614188.05645,,1857,30.5999,30.5999,0.23704174,9.8999999E-6,30.793527,0.66400972,389.24115,0.8782,189.83448,0.4144,579.07562,0.8782,21.716486,15.10823,0.26573454,92.056843,,,1,,,,3.9850582E-5,29.988255,948.24129,12.640356,0
3816614723.27299,,1857,30.8001,30.8001,0.22518967,9.8999999E-6,31.000703,0.67560277,393.41618,0.8775,192.31224,0.4192,585.72842,0.8775,1.6648501,15.071468,0.2652176,92.060135,,,1,,,,4.0403722E-5,30.324206,961.04359,12.690557,0
3816615273.38269,,1857,31.0005,31.0005,0.21333757,9.8999999E-6,31.200781,0.67851776,396.79614,0.8952,194.71402,0.4241,591.51016,0.8952,10.642433,15.184543,0.26958025,92.001855,,,1,,,,4.0507344E-5,30.326849,973.48875,12.717507,0
3816615919.17937,,1857,31.4004,31.4004,0.2963022,9.8999999E-6,31.594831,0.67608094,404.03618,0.9227,199.45561,0.4351,603.49179,0.9227,10.144495,15.362926,0.27485046,91.959064,,,1,,,,4.0851131E-5,30.465602,998.23337,12.788047,0
3816616500.25233,,1857,31.6001,31.6001,0.36741471,9.8999999E-6,31.802876,0.68807733,408.34212,0.9235,201.98402,0.4418,610.32615,0.9235,9.8427167,15.350612,0.27534536,91.944413,,,1,,,,4.1348027E-5,30.796358,1011.4229,12.839786,0
3816617067.71615,,1857,31.8001,31.8001,0.22518967,9.8999999E-6,32.002354,0.68615685,412.3793,0.9291,204.39667,0.4489,616.77598,0.9291,5.3828793,15.340312,0.27709477,91.894325,,,1,,,,4.1821956E-5,30.682867,1024.1507,12.885905,0
3816617700.97535,,1857,32.2004,32.2004,0.15407714,9.8999999E-6,32.395208,0.68075185,420.11501,0.9764,209.17174,0.4647,629.28675,0.9764,11.456885,15.451218,0.28222255,91.81808,,,1,,,,4.237619E-5,30.707733,1049.4495,12.968431,0
3816618254.98121,,1857,32.4007,32.4007,0.16592923,9.8999999E-6,32.602468,0.68846719,424.91702,0.9632,211.67264,0.4739,636.58966,0.9632,1.7647459,15.33681,0.28174765,91.772696,,,1,,,,4.3197517E-5,30.898328,1062.9209,13.033278,0
3816618836.57443,,1857,32.6002,32.6002,0.16592923,9.8999999E-6,32.7986,0.68313021,429.10767,0.9844,214.09785,0.4831,643.20552,0.9844,8.9719081,15.286502,0.28519962,91.649928,,,1,,,,4.3816716E-5,30.625974,1075.7482,13.083109,0
3816619483.0749,,1857,33.0005,33.0005,-0.24889384,9.8999999E-6,33.188664,0.67320232,437.24695,1.042,218.88513,0.502,656.13208,1.042,11.265922,15.302832,0.2898637,91.53364,,,1,,,,4.4673163E-5,30.458989,1101.4874,13.174587,0
3816620050.75083,,1857,33.1999,33.1999,0.21333757,9.8999999E-6,33.401382,0.7009711,438.98353,1.015,221.5513,0.5126,660.53483,1.015,11.601668,15.762601,0.29398235,91.689307,,,1,,,,4.3616014E-5,31.105967,1115.6523,13.142676,0
3816620635.83697,,1857,33.4009,33.4009,-0.023704175,9.8999999E-6,33.613818,0.72298144,441.70049,1.017,224.20885,0.523,665.90934,1.017,1.4983117,16.102914,0.29430733,91.873042,,,1,,,,4.2993964E-5,32.102081,1129.8888,13.140444,0
3816621276.31658,,1857,33.8002,33.8002,-0.04740835,9.8999999E-6,34.011994,0.72833661,449.18435,1.047,229.22507,0.5416,678.40942,1.047,9.0835975,16.501338,0.30318968,91.846379,,,1,,,,4.2743574E-5,32.570666,1156.8158,13.206646,0
3816621873.64784,,1857,34.0001,34.0001,-0.26074591,9.8999999E-6,34.224313,0.74700859,453.66716,1.025,231.89741,0.5507,685.56456,1.025,9.0609238,16.563459,0.30194114,91.915154,,,1,,,,4.3015232E-5,33.226461,1171.3036,13.255698,0
3816622475.81213,,1857,34.2001,34.2001,0.071112528,9.8999999E-6,34.427027,0.75055888,457.94668,1.083,234.47828,0.5588,692.42496,1.083,1.2559399,16.665562,0.30513735,91.884854,,,1,,,,4.3184442E-5,33.372763,1185.2202,13.301952,0
3816623162.75877,,1857,34.6005,34.6005,0.10666879,9.8999999E-6,34.820015,0.7481631,466.30229,1.106,239.51227,0.5725,705.81456,1.106,9.9368049,16.944016,0.3124757,91.836103,,,1,,,,4.3303538E-5,33.540945,1212.4334,13.391789,0
3816623739.9713,,1857,34.8004,34.8004,0.011852087,9.8999999E-6,35.032287,0.76464257,470.28254,1.091,242.23354,0.5789,712.51608,1.091,1.3337396,16.940893,0.31056172,91.892791,,,1,,,,4.3706842E-5,34.069466,1227.2611,13.42426,0
3816624353.48397,,1857,35.0002,35.0002,0.11852087,9.8999999E-6,35.231724,0.76725392,474.4366,1.06,244.82582,0.5843,719.26242,1.06,10.352806,17.048491,0.31258236,91.897077,,,1,,,,4.3839187E-5,34.12012,1241.2744,13.466176,0
3816625051.82511,,1857,35.4001,35.4001,0.13037296,9.8999999E-6,35.626042,0.7644499,482.09613,1.13,249.98235,0.5939,732.07848,1.13,9.3043782,17.285685,0.32010095,91.830932,,,1,,,,4.4017611E-5,34.271018,1269.2149,13.532127,0
3816625672.52373,,1857,35.5997,35.5997,0.10666879,9.8999999E-6,35.83572,0.77989657,486.25657,1.107,252.76476,0.5985,739.02133,1.107,6.5187112,17.306627,0.32030634,91.84295,,,1,,,,4.4375746E-5,34.74128,1284.1989,13.569047,0
3816626277.56451,,1857,35.8003,35.8003,0,9.8999999E-6,36.03774,0.77991712,490.36532,1.155,255.43778,0.6026,745.80309,1.155,1.0553605,17.3347,0.32112484,91.841656,,,1,,,,4.4708335E-5,34.673158,1298.7187,13.606994,0
3816626966.10647,,1857,36.2001,36.2001,0.04740835,9.8999999E-6,36.429134,0.77654896,498.16703,1.156,260.66874,0.6103,758.83577,1.156,9.8039057,17.610498,0.32984811,91.765197,,,1,,,,4.4789558E-5,34.784588,1327.0818,13.674962,0
3816627595.50869,,1857,36.3997,36.3997,0.011852087,9.8999999E-6,36.64119,0.79203128,502.2803,1.162,263.4992,0.6143,765.7795,1.162,1.1830985,17.541414,0.32626679,91.829833,,,1,,,,4.5359425E-5,35.318678,1342.5768,13.708078,0
3816628227.52149,,1857,36.6,36.6,-0.34371054,9.8999999E-6,36.841623,0.79882418,503.66414,1.152,266.22735,0.6182,769.89149,1.152,0.98264549,17.703398,0.32780939,91.88812,,,1,,,,4.5163639E-5,35.449057,1357.3052,13.671063,0
3816628908.40454,,1857,36.9998,36.9998,-0.34371054,9.8999999E-6,37.237997,0.79963146,509.07571,1.157,271.64814,0.6263,780.72385,1.157,6.8093739,18.024201,0.3362617,91.854871,,,1,,,,4.498065E-5,35.606709,1386.6685,13.670867,0
3816629512.34215,,1857,37.2002,37.2002,-0.402971,9.8999999E-6,37.452877,0.81935951,511.73566,1.135,274.58935,0.6309,786.32502,1.135,1.2217268,18.017531,0.33392683,91.923863,,,1,,,,4.5298008E-5,36.241305,1402.718,13.663454,0
3816630154.74308,,1857,37.4004,37.4004,0.035556264,9.8999999E-6,37.652035,0.82225571,514.65646,1.146,277.34793,0.6353,792.00439,1.146,1.1791068,18.106941,0.33679411,91.907101,,,1,,,,4.5398752E-5,36.304065,1417.6757,13.668755,0
3816630887.83125,,1857,37.8004,37.8004,0.082964614,9.8999999E-6,38.043597,0.8218813,521.7768,1.164,282.81202,0.6445,804.58882,1.164,7.8483538,18.421626,0.34587771,91.847676,,,1,,,,4.5339076E-5,36.499832,1447.3153,13.715233,0
3816631538.71676,,1857,37.9997,37.9997,0.13037296,9.8999999E-6,38.256575,0.83928353,524.8087,1.162,285.81937,0.6497,810.62807,1.162,1.0997092,18.403826,0.34390445,91.89941,,,1,,,,4.5706226E-5,37.014947,1463.5655,13.718131,0
3816632192.48789,,1857,38.2,38.2,0.011852087,9.8999999E-6,38.457146,0.84119406,528.00804,1.173,288.64846,0.6547,816.6565,1.173,1.1722741,18.473315,0.34538899,91.905527,,,1,,,,4.5867144E-5,37.0401,1478.9521,13.729777,0
3816632937.95706,,1857,38.5997,38.5997,0.023704175,9.8999999E-6,38.849286,0.8404415,535.59993,1.184,294.18483,0.6649,829.78477,1.184,6.165175,18.78265,0.35413752,91.85083,,,1,,,,4.5843857E-5,37.246096,1509.267,13.786609,0
3816633603.11401,,1857,38.8,38.8,-0.22518967,9.8999999E-6,39.064041,0.85680095,538.80986,1.184,297.27184,0.6707,836.0817,1.184,1.2082918,18.76711,0.35330524,91.875419,,,1,,,,4.6219126E-5,37.763075,1525.9993,13.792988,0
3816634267.67617,,1857,39.0002,39.0002,-0.24889384,9.8999999E-6,39.264133,0.85952527,542.24017,1.198,300.14822,0.6763,842.38839,1.198,0.96934246,18.855367,0.35527395,91.877417,,,1,,,,4.6345464E-5,37.791741,1541.6722,13.810063,0
3816635016.97188,,1857,39.3998,39.3998,-0.13037296,9.8999999E-6,39.656509,0.85722094,549.654,1.209,305.82183,0.6876,855.47583,1.209,5.9277313,19.155374,0.36396777,91.823649,,,1,,,,4.6334516E-5,37.939165,1572.6387,13.860373,0
3816635668.49194,,1857,39.6001,39.6001,0.2963022,9.8999999E-6,39.869209,0.87429024,553.24376,1.203,308.89138,0.6938,862.13514,1.203,1.1416709,19.123907,0.36159192,91.872702,,,1,,,,4.6756642E-5,38.475851,1589.5539,13.876467,0
3816636347.25684,,1857,39.8011,39.8011,0.2963022,9.8999999E-6,40.069668,0.87726477,556.69047,1.184,311.82429,0.6998,868.51477,1.184,6.7700166,19.244595,0.36531054,91.849637,,,1,,,,4.6808651E-5,38.507631,1605.5783,13.893064,0
3816637088.60263,,1857,40.2004,40.2004,0.22518967,9.8999999E-6,40.461552,0.87282397,564.45989,1.228,317.57587,0.7113,882.03577,1.228,5.1444825,19.526281,0.37293368,91.81196,,,1,,,,4.6854907E-5,38.558596,1637.1372,13.950525,0
3816637751.80006,,1857,40.4,40.4,0.24889384,9.8999999E-6,40.675892,0.8911545,567.78567,1.231,320.7171,0.7173,888.50278,1.231,0.97406191,19.472037,0.37020137,91.859526,,,1,,,,4.731418E-5,39.201992,1654.5282,13.958776,0
3816638439.72992,,1857,40.6006,40.6006,0.2014855,9.8999999E-6,40.879025,0.89303512,571.44748,1.238,323.72842,0.7227,895.1759,1.238,0.91585045,19.563998,0.37226498,91.860418,,,1,,,,4.7441731E-5,39.193771,1671.0947,13.97899,0
3816639194.91615,,1857,41.0003,41.0003,0.15407714,9.8999999E-6,41.268801,0.88950118,578.94577,1.261,329.53446,0.7321,908.48023,1.261,5.9749912,19.866895,0.38200659,91.788214,,,1,,,,4.7423577E-5,39.289809,1703.114,14.028655,0
3816639888.79898,,1857,41.1996,41.1996,0.26074591,9.8999999E-6,41.483617,0.90773297,582.27264,1.261,332.76717,0.7366,915.03982,1.261,1.0915876,19.828605,0.37949741,91.836609,,,1,,,,4.7842109E-5,39.918085,1720.8905,14.036207,0
3816640563.17552,,1857,41.4001,41.4001,0.24889384,9.8999999E-6,41.683788,0.9081126,586.00899,1.272,335.76948,0.7402,921.77848,1.272,0.89769415,19.903131,0.38094421,91.842924,,,1,,,,4.8009344E-5,39.819023,1737.5381,14.058439,0
3816641325.32714,,1857,41.8001,41.8001,0.15407714,9.8999999E-6,42.081121,0.90614336,593.41789,1.291,341.76727,0.7454,935.18516,1.291,5.4323329,20.235875,0.39234286,91.75161,,,1,,,,4.7921391E-5,40.004909,1770.8208,14.10176,0
3816642029.72973,,1857,41.9999,41.9999,0.17778131,9.8999999E-6,42.291784,0.92404769,597.19728,1.289,344.9308,0.747,942.12808,1.289,1.0109578,20.172624,0.3878667,91.826833,,,1,,,,4.8407521E-5,40.620187,1788.595,14.120882,0
3816642734.83575,,1857,42.2,42.2,0.17778131,9.8999999E-6,42.482965,0.92552997,601.15298,1.244,347.83807,0.7477,948.99106,1.244,5.2700214,20.302514,0.39166901,91.804434,,,1,,,,4.8451161E-5,40.547637,1804.8024,14.150448,0
3816643505.06258,,1857,42.5998,42.5998,0.14222506,9.8999999E-6,42.877294,0.92169683,608.82091,1.303,353.84739,0.7468,962.6683,1.303,5.4123836,20.583113,0.40027704,91.750761,,,1,,,,4.8486298E-5,40.692837,1838.4623,14.199145,0
3816644237.55931,,1857,42.7996,42.7996,0.21333757,9.8999999E-6,43.09552,0.9411877,612.38176,1.247,357.17079,0.7454,969.55255,1.247,6.963595,20.574429,0.39759485,91.81099,,,1,,,,4.8835224E-5,41.337803,1857.2238,14.209871,0
3816644951.76553,,1857,43.0011,43.0011,0.15407714,9.8999999E-6,43.294251,0.94124248,615.89763,1.276,360.26647,0.7439,976.16411,1.276,4.8261033,20.655123,0.40040064,91.79311,,,1,,,,4.8976663E-5,41.238588,1874.3921,14.225853,0
3816645731.76513,,1857,43.3992,43.3992,0.059260435,9.8999999E-6,43.68526,0.93921856,623.74835,1.302,366.27454,0.741,990.0229,1.302,4.7510216,20.943518,0.40889527,91.744964,,,1,,,,4.8994302E-5,41.498146,1908.4019,14.278234,0
3816646455.24387,,1857,43.6006,43.6006,0.04740835,9.8999999E-6,43.89917,0.95762286,627.22337,1.272,369.62746,0.7399,996.85082,1.272,7.2169799,20.928665,0.4072864,91.780281,,,1,,,,4.9354448E-5,42.079049,1927.1371,14.287818,0
3816647159.71346,,1857,43.7993,43.7993,0.071112528,9.8999999E-6,44.098006,0.95764679,630.75059,1.259,372.73654,0.7394,1003.4871,1.259,4.4690423,21.003798,0.40850798,91.792005,,,1,,,,4.9499039E-5,41.942425,1944.6341,14.303381,0
3816647969.48917,,1857,44.2005,44.2005,0.082964614,9.8999999E-6,44.490534,0.95501224,638.65835,1.33,378.93417,0.741,1017.5925,1.33,5.6440141,21.313869,0.41860535,91.72261,,,1,,,,4.9475609E-5,42.182835,1979.4076,14.354927,0
3816648701.96048,,1857,44.4008,44.4008,0.11852087,9.8999999E-6,44.704716,0.97352334,642.04653,1.278,382.31981,0.7437,1024.3663,1.278,5.9807712,21.27709,0.41591061,91.770168,,,1,,,,4.9875268E-5,42.750629,1998.5116,14.361942,0
3816649457.70728,,1857,44.5998,44.5998,0.10666879,9.8999999E-6,44.905282,0.97521443,645.58865,1.277,385.53277,0.7476,1031.1214,1.277,5.1467512,21.353197,0.41754647,91.774372,,,1,,,,5.0020559E-5,42.735189,2016.4844,14.376675,0
3816650255.93447,,1857,44.9998,44.9998,0.059260435,9.8999999E-6,45.294867,0.97080827,653.43372,1.351,391.83563,0.7602,1045.2694,1.351,4.4290088,21.657677,0.42776036,91.702955,,,1,,,,5.0005365E-5,42.865916,2051.6249,14.42622,0
3816651015.79395,,1857,45.2005,45.2005,0.17778131,9.8999999E-6,45.509678,0.98964103,656.69027,1.295,395.32344,0.7702,1052.0137,1.295,6.8323708,21.620531,0.42437575,91.763327,,,1,,,,5.0395234E-5,43.437242,2071.1308,14.429684,0
3816651760.02617,,1857,45.4012,45.4012,0.11852087,9.8999999E-6,45.710303,0.99086117,660.27836,1.302,398.62835,0.7818,1058.9067,1.302,4.3649374,21.706952,0.42735882,91.745791,,,1,,,,5.0523859E-5,43.40175,2089.4318,14.444848,0
3816652590.63877,,1857,45.8005,45.8005,0.082964614,9.8999999E-6,46.100087,0.9871248,667.58511,1.381,405.11131,0.8097,1072.6964,1.381,3.9841881,21.986514,0.43567795,91.705318,,,1,,,,5.0533821E-5,43.559479,2125.218,14.481212,0
3816653362.61425,,1857,45.9996,45.9996,0.16592923,9.8999999E-6,46.316069,1.0061802,670.88545,1.354,408.76185,0.8277,1079.6473,1.354,6.3225078,21.968971,0.43407144,91.73871,,,1,,,,5.0888719E-5,44.168396,2145.1782,14.484939,0
3816654138.47872,,1857,46.2003,46.2003,0.071112528,9.8999999E-6,46.515727,1.0072008,674.47861,1.37,412.13186,0.8455,1086.6105,1.37,5.3371566,22.042305,0.43600026,91.736602,,,1,,,,5.1043251E-5,44.107703,2163.7129,14.500012,0
3816654976.1755,,1857,46.6007,46.6007,0.10666879,9.8999999E-6,46.906786,1.0030953,681.60521,1.465,418.78338,0.8823,1100.3886,1.465,3.5919715,22.336157,0.44622126,91.668502,,,1,,,,5.101916E-5,44.260849,2200.2465,14.531058,0
3816655758.00342,,1857,46.7998,46.7998,-0.32000637,9.8999999E-6,47.119745,1.0221337,685.22111,1.405,422.40513,0.9028,1107.6262,1.405,5.2205341,22.304666,0.44328803,91.718832,,,1,,,,5.1410949E-5,44.830376,2220.2703,14.542123,0
3816656518.87019,,1857,47.0001,47.0001,0.1896334,9.8999999E-6,47.32226,1.0224664,688.49832,1.484,425.87709,0.9224,1114.3754,1.484,0.60339152,22.32413,0.44328716,91.733981,,,1,,,,5.1670992E-5,44.78758,2239.3963,14.549143,0
3816657348.11605,,1857,47.4001,47.4001,0.14222506,9.8999999E-6,47.71084,1.0193603,695.74609,1.507,432.59359,0.9591,1128.3397,1.507,4.0029711,22.666239,0.45480942,91.660586,,,1,,,,5.1539171E-5,44.962827,2276.3242,14.582558,0
3816658117.44042,,1857,47.5997,47.5997,0.059260435,9.8999999E-6,47.926126,1.0382024,699.13623,1.459,436.30137,0.9781,1135.4376,1.459,6.6402951,22.636756,0.45239152,91.702157,,,1,,,,5.1916177E-5,45.506065,2296.9135,14.587789,0
3816658910.99691,,1857,47.8002,47.8002,0.035556264,9.8999999E-6,48.126825,1.0387619,702.55104,1.497,439.83561,0.995,1142.3867,1.497,3.7771631,22.725684,0.45579661,91.680262,,,1,,,,5.2030382E-5,45.44149,2316.1913,14.59791,0
3816659770.13512,,1857,48.2002,48.2002,0,9.8999999E-6,48.517273,1.0350662,710.02772,1.548,446.58588,1.023,1156.6136,1.548,4.1036743,23.012319,0.46476918,91.633795,,,1,,,,5.2026871E-5,45.621737,2353.9258,14.634535,0
3816660523.97179,,1857,48.4002,48.4002,0.035556264,9.8999999E-6,48.733862,1.0530555,713.52345,1.584,450.37914,1.036,1163.9026,1.584,0.66263957,22.931707,0.460438,91.689963,,,1,,,,5.2520646E-5,46.188508,2374.9893,14.641225,0
3816661327.48355,,1857,48.6009,48.6009,0,9.8999999E-6,48.932823,1.0548807,716.85932,1.525,453.85586,1.045,1170.7152,1.525,4.021829,23.053784,0.46421608,91.673389,,,1,,,,5.2548128E-5,46.109753,2394.4212,14.649866,0
3816662198.11169,,1857,49.0004,49.0004,0.14222506,9.8999999E-6,49.32217,1.0502031,724.15537,1.586,460.65864,1.058,1184.814,1.586,4.6829895,23.34624,0.47437304,91.609815,,,1,,,,5.2523273E-5,46.260741,2432.6765,14.682147,0
3816662985.72499,,1857,49.2004,49.2004,0.1896334,9.8999999E-6,49.538474,1.0691177,727.90192,1.626,464.41663,1.061,1192.3185,1.626,0.61763647,23.257005,0.46799842,91.696133,,,1,,,,5.3034187E-5,46.846598,2454.0604,14.693669,0
3816663776.95828,,1857,49.4003,49.4003,0.1896334,9.8999999E-6,49.739153,1.0703536,731.16124,1.626,467.93884,1.063,1199.1001,1.626,0.52273208,23.319379,0.46966499,91.69583,,,1,,,,5.3189006E-5,46.799756,2473.9833,14.699913,0
3816664631.29948,,1857,49.8,49.8,-0.26074591,9.8999999E-6,50.130159,1.0649868,738.63056,1.595,474.84027,1.063,1213.4708,1.595,4.3968441,23.672749,0.48233597,91.610688,,,1,,,,5.3036927E-5,46.836532,2513.0328,14.734255,0
3816665447.39617,,1857,50,50,-0.22518967,9.8999999E-6,50.345429,1.086114,741.97682,1.566,478.68753,1.061,1220.6644,1.566,4.5614304,23.642215,0.47980422,91.651217,,,1,,,,5.3405697E-5,47.538059,2534.6622,14.73772,0
3816666242.72604,,1857,50.1998,50.1998,-0.28445011,9.8999999E-6,50.54376,1.0848909,745.79438,1.562,482.21706,1.058,1228.0114,1.562,3.2475805,23.729023,0.48298289,91.631932,,,1,,,,5.3532092E-5,47.320934,2554.6717,14.755419,0
3816667105.5705,,1857,50.5993,50.5993,-0.2963022,9.8999999E-6,50.933601,1.0802529,753.22404,1.624,489.21238,1.05,1242.4364,1.624,4.8411839,24.025318,0.49289654,91.576508,,,1,,,,5.3499831E-5,47.487712,2594.2317,14.788352,0
3816667912.17781,,1857,50.7998,50.7998,0,9.8999999E-6,51.149121,1.1016065,756.45851,1.554,493.0895,1.044,1249.548,1.554,4.9453858,23.975075,0.48883291,91.635377,,,1,,,,5.3899758E-5,48.154052,2616.2326,14.789277,0
3816668741.50275,,1857,50.9999,50.9999,-0.023704175,9.8999999E-6,51.349181,1.1025392,759.82429,1.549,496.73043,1.039,1256.5547,1.549,4.1652089,24.04122,0.49085582,91.630357,,,1,,,,5.4049977E-5,48.08711,2636.7384,14.797204,0
3816669612.82263,,1857,51.4003,51.4003,0.011852087,9.8999999E-6,51.73928,1.0973884,767.44649,1.596,503.90288,1.028,1271.3494,1.596,4.4438378,24.338264,0.50066272,91.577831,,,1,,,,5.4025256E-5,48.25061,2676.953,14.832957,0
3816670427.76382,,1857,51.6003,51.6003,0.082964614,9.8999999E-6,51.954875,1.1175267,770.87849,1.538,507.88587,1.021,1278.7644,1.538,4.854567,24.291528,0.49681966,91.632782,,,1,,,,5.4426991E-5,48.838413,2699.309,14.837462,0
3816671268.95134,,1857,51.7998,51.7998,0.22518967,9.8999999E-6,52.155749,1.1187232,774.33072,1.549,511.65094,1.016,1285.9817,1.549,4.1821029,24.372836,0.49943461,91.623254,,,1,,,,5.4549728E-5,48.776844,2720.2222,14.846507,0
3816672176.21064,,1857,52.1999,52.1999,0.30815428,9.8999999E-6,52.544338,1.1133073,781.58546,1.606,519.02474,1.007,1300.6102,1.606,3.5671632,24.689851,0.51116859,91.548678,,,1,,,,5.447249E-5,48.899431,2760.9075,14.87478,0
3816673022.22139,,1857,52.3997,52.3997,0.16592923,9.8999999E-6,52.763998,1.134121,784.44152,1.551,523.27182,1.002,1307.7133,1.551,4.1954167,24.625053,0.50716103,91.601443,,,1,,,,5.4895106E-5,49.53926,2784.0394,14.866984,0
3816673845.90298,,1857,52.6,52.6,0.23704174,9.8999999E-6,52.960738,1.1341699,787.93741,1.542,527.07874,0.9986,1315.0162,1.542,3.3108028,24.690792,0.508305,91.610635,,,1,,,,5.5048504E-5,49.418032,2804.8398,14.877765,0
3816674760.76494,,1857,52.9997,52.9997,0.14222506,9.8999999E-6,53.350521,1.1288361,794.94241,1.623,534.7138,0.993,1329.6562,1.623,3.6071425,25.008968,0.52132974,91.518622,,,1,,,,5.4967104E-5,49.561396,2846.2781,14.900368,0
3816675620.13787,,1857,53.1998,53.1998,0.11852087,9.8999999E-6,53.567666,1.1496058,798.10651,1.546,538.98363,0.9907,1337.0901,1.546,4.1731032,24.950584,0.51735184,91.570907,,,1,,,,5.5385555E-5,50.165701,2869.4949,14.899034,0
3816676476.02793,,1857,53.3998,53.3998,0.16592923,9.8999999E-6,53.768142,1.1502481,801.25795,1.545,542.97357,0.9889,1344.2315,1.545,3.5317544,25.014102,0.51880797,91.575643,,,1,,,,5.5533897E-5,50.071788,2891.0131,14.902095,0
3816677400.02284,,1857,53.8002,53.8002,0.1896334,9.8999999E-6,54.155679,1.1444229,808.26097,1.61,550.76062,0.9865,1359.0216,1.61,2.8933872,25.325285,0.53033114,91.507161,,,1,,,,5.5463263E-5,50.183744,2932.8375,14.924769,0
3816678238.69298,,1857,54,54,-0.27259803,9.8999999E-6,54.371137,1.165232,811.5713,1.653,555.09243,0.9858,1366.6637,1.653,0.50758187,25.21507,0.52352376,91.58553,,,1,,,,5.5994794E-5,50.840449,2956.2206,14.926509,0
3816679106.88533,,1857,54.2003,54.2003,0.15407714,9.8999999E-6,54.570814,1.1659829,814.66615,1.55,559.16562,0.9854,1373.8318,1.55,2.5927645,25.347779,0.52927236,91.545572,,,1,,,,5.5998185E-5,50.683699,2977.9737,14.928605,0
3816680016.23804,,1857,54.5994,54.5994,0.21333757,9.8999999E-6,54.959693,1.159072,821.30387,1.613,567.13791,0.9853,1388.4418,1.613,3.4031183,25.653405,0.54161712,91.465359,,,1,,,,5.5929623E-5,50.71532,3020.5679,14.943749,0
3816680890.40191,,1857,54.7999,54.7999,0.24889384,9.8999999E-6,55.176552,1.1816073,824.48964,1.558,571.6481,0.9857,1396.1377,1.558,3.9056322,25.600822,0.53767169,91.517087,,,1,,,,5.6336889E-5,51.466643,3044.4519,14.942754,0
3816681764.73505,,1857,55.0001,55.0001,0.28445011,9.8999999E-6,55.376972,1.1822293,827.34528,1.557,575.79854,0.9863,1403.1438,1.557,3.1862257,25.663461,0.54018837,91.505878,,,1,,,,5.6478505E-5,51.350622,3066.609,14.940241,0
3816682706.19109,,1857,55.3994,55.3994,-0.16592923,9.8999999E-6,55.764906,1.1757706,834.03216,1.62,583.87532,0.9879,1417.9075,1.62,3.6838313,25.963444,0.55152236,91.440871,,,1,,,,5.6420034E-5,51.456934,3109.7247,14.956219,0
3816683563.51676,,1857,55.6002,55.6002,0.27259803,9.8999999E-6,55.985089,1.197132,837.1013,1.692,588.44848,0.989,1425.5498,1.692,0.44890532,25.853241,0.54497439,91.512841,,,1,,,,5.6942672E-5,52.130164,3134.3302,14.952219,0
3816684448.66094,,1857,55.8005,55.8005,0.24889384,9.8999999E-6,56.181821,1.1977487,840.10237,1.576,592.57938,0.9901,1432.6818,1.576,3.0482846,25.969206,0.54884126,91.497682,,,1,,,,5.6970535E-5,51.958363,3156.397,14.953278,0
3816685402.68577,,1857,56.2001,56.2001,-0.27259803,9.8999999E-6,56.569779,1.1916347,847.01316,1.636,600.74672,0.9926,1447.7599,1.636,3.3384902,26.28549,0.56149171,91.418719,,,1,,,,5.6887854E-5,52.092255,3200.1399,14.972892,0
3816686295.49614,,1857,56.3998,56.3998,-0.30815428,9.8999999E-6,56.788793,1.213514,849.65073,1.588,605.4039,0.9941,1455.0546,1.588,4.0413782,26.218231,0.55709879,91.471522,,,1,,,,5.7301742E-5,52.738929,3224.967,14.961592,0
3816687189.76377,,1857,56.6002,56.6002,-0.16592923,9.8999999E-6,56.989591,1.2137828,852.49051,1.574,609.65118,0.9957,1462.1417,1.574,2.6766866,26.29062,0.55984088,91.460244,,,1,,,,5.741949E-5,52.597878,3247.8135,14.958706,0
3816688147.71416,,1857,57.0001,57.0001,-0.1896334,9.8999999E-6,57.376206,1.2074192,859.41474,1.646,617.85789,0.999,1477.2726,1.646,3.9593309,26.611423,0.57307439,91.375652,,,1,,,,5.7326318E-5,52.726084,3292.029,14.978591,0
3816689047.39867,,1857,57.201,57.201,-0.17778131,9.8999999E-6,57.594983,1.2299499,862.24387,1.594,622.48849,1.001,1484.7324,1.594,4.244698,26.546184,0.56865786,91.427565,,,1,,,,5.7738789E-5,53.377849,3317.1821,14.970816,0
3816689947.16328,,1857,57.4001,57.4001,0.22518967,9.8999999E-6,57.79494,1.2299591,865.27265,1.587,626.74522,1.003,1492.0179,1.587,2.1632804,26.600253,0.56931676,91.440793,,,1,,,,5.7896048E-5,53.238203,3340.2551,14.971426,0
3816690887.0613,,1857,57.8006,57.8006,0.22518967,9.8999999E-6,58.178167,1.223981,872.17478,1.663,634.93777,1.008,1507.1126,1.663,3.3589321,26.927539,0.5832535,91.349277,,,1,,,,5.7784849E-5,53.392677,3384.6991,14.991445,0
3816691795.71543,,1857,58.0002,58.0002,0.28445011,9.8999999E-6,58.400737,1.2462717,874.90459,1.594,639.6761,1.011,1514.5807,1.594,3.3125198,26.853302,0.57734406,91.419273,,,1,,,,5.8208631E-5,54.000634,3410.646,14.981054,0
3816692681.61935,,1857,58.1997,58.1997,-0.13037296,9.8999999E-6,58.602639,1.2459493,877.81181,1.598,643.99864,1.014,1521.8104,1.598,2.9661501,26.904475,0.57795157,91.432312,,,1,,,,5.8366972E-5,53.845818,3434.2693,14.979049,0
3816693662.29131,,1857,58.5998,58.5998,0.22518967,9.8999999E-6,58.990639,1.2393844,884.6975,1.674,652.33641,1.021,1537.0339,1.674,3.4924129,27.227754,0.5917528,91.343063,,,1,,,,5.8264158E-5,53.955929,3479.8954,14.997252,0
3816694581.31359,,1857,58.8005,58.8005,0.2014855,9.8999999E-6,59.207683,1.2622392,887.38136,1.619,657.04289,1.025,1544.4243,1.619,3.5694897,27.162584,0.58736116,91.392702,,,1,,,,5.8666681E-5,54.634364,3505.5498,14.987605,0
3816695499.92858,,1857,59.0004,59.0004,0.15407714,9.8999999E-6,59.407987,1.2621288,890.37882,1.628,661.35366,1.029,1551.7325,1.628,2.2342495,27.221911,0.58986625,91.380615,,,1,,,,5.8813809E-5,54.475038,3529.3089,14.987527,0
3816696484.58957,,1857,59.4,59.4,0.11852087,9.8999999E-6,59.792821,1.2551584,897.35597,1.698,669.65469,1.038,1567.0107,1.698,2.9796617,27.538311,0.60190837,91.31545,,,1,,,,5.8718578E-5,54.607903,3575.1815,15.007754,0
3816697408.20225,,1857,59.6001,59.6001,0.1896334,9.8999999E-6,60.01233,1.2781739,900.18047,1.631,674.36857,1.044,1574.549,1.631,2.8507236,27.456124,0.59586744,91.381732,,,1,,,,5.9156072E-5,55.24139,3601.4797,14.999925,0
3816698307.61852,,1857,59.7998,59.7998,0.21333757,9.8999999E-6,60.210686,1.2765384,903.3453,1.642,678.64845,1.049,1581.9937,1.642,2.3508742,27.529002,0.59767695,91.383138,,,1,,,,5.9273744E-5,54.959578,3625.3267,15.003073,0
3816699021.42549,,1857,60,60,0.24889384,9.8999999E-6,60.41483,1.2815781,906.55325,1.654,683.07065,1.055,1589.6239,1.654,2.4642923,27.58838,0.59856041,91.393611,,,1,,,,5.9424418E-5,55.231031,3649.9516,15.005475,0