File: MPMS/MPMS_CrCl2pym_ZFC.rso.dat
[Header]
TITLE,MPMS RSO Measurement
BYAPP,MPMS Measurement,1.1,Summary
FILEOPENTIME, 1611847659.361000 1/28/2021, 3:27:39 PM

INFO, APPNAME, MPMS MultiVu Application, Revision 1.61,  Build 082

INFO, NAME, sicogi_CrCl2pym
INFO, WEIGHT, 26.600
INFO, AREA, 1.000
INFO, LENGTH, 1.000
INFO, SHAPE, 0
INFO, COMMENT, eicosane 44.5
INFO, SEQUENCE FILE: JP_ZFC_FC_MH_280121.seq


INFO, BACKGROUND DATA FILE:, None


STARTUPAXIS,X,4,LINEAR,AUTO,0.000000,0.000000
STARTUPAXIS,Y1,5,LINEAR,AUTO,0.000000,0.000000


STARTUPGROUP,Longitudinal
FIELDGROUP,Longitudinal,1,2,3,4,5,6,7,8,9,10,11,19,20,21,22,23,35
FIELDGROUP,Transverse,1,2,3,4,12,13,14,15,16,17,18,24,25,26,27,28,35

PLOT_APPEARANCE,ALL,HORZ_GRID_ON,VERT_GRID_ON,MARKERS_AND_LINES

[Data]
Time,Comment,Field (Oe),Temperature (K),Long Moment (emu),Long Scan Std Dev,Long Offset (cm),Long Offset Std Dev,Long Algorithm,Long Reg Fit,Long Reg Factor,Trans Moment (emu),Trans Scan Std Dev,Trans Offset (cm),Trans Offset Std Dev,Trans Algorithm,Trans Reg Fit,Trans Reg Factor,Long Moment [w/o ABS] (emu),Long Scan Std Dev [w/o ABS],Long Offset [w/o ABS] (cm),Long Offset Std Dev [w/o ABS],Long Reg Fit [w/o ABS],Trans Moment [w/o ABS] (emu),Trans Scan Std Dev [w/o ABS],Trans Offset [w/o ABS] (cm),Trans Offset Std Dev [w/o ABS],Trans Reg Fit [w/o ABS],RSO Position (deg),Amplitude (cm),Frequency,Cycles to Average,Scans per Measurement,Delta Temp (K),Error,EC Comp. Running,Using ABS,
1611847659.345,,1.000000e+002,3.691721e+000,3.831249e-004,9.234079e-007,3.977140e-002,1.491714e-004,3,9.722756e-001,1.825000e+000,,,,,,,,,,,,,,,,,,0,5.000000e+000,1.000000e+000,4,4,2.234149e-001,0,,0,
1611851438.031,,1.000000e+002,2.002797e+000,4.190633e-004,2.673537e-008,2.957805e-002,2.462653e-005,3,9.599986e-001,1.825000e+000,,,,,,,,,,,,,,,,,,0,5.000000e+000,1.000000e+000,4,4,4.083991e-003,0,,0,
1611851649.130,,1.000000e+002,2.252528e+000,4.110619e-004,1.811437e-008,3.165524e-002,1.118973e-005,3,9.630658e-001,1.825000e+000,,,,,,,,,,,,,,,,,,0,5.000000e+000,1.000000e+000,4,4,5.383968e-003,0,,0,
1611851853.881,,1.000000e+002,2.502924e+000,4.047745e-004,3.437076e-008,3.324507e-002,4.957380e-005,3,9.653239e-001,1.825000e+000,,,,,,,,,,,,,,,,,,0,5.000000e+000,1.000000e+000,4,4,5.409002e-003,0,,0,
1611852077.179,,1.000000e+002,2.752640e+000,3.993521e-004,3.929853e-008,3.454972e-002,2.290555e-005,3,9.671700e-001,1.825000e+000,,,,,,,,,,,,,,,,,,0,5.000000e+000,1.000000e+000,4,4,6.603003e-003,0,,0,
1611852332.880,,1.000000e+002,3.001942e+000,3.945423e-004,2.199791e-008,3.567854e-002,3.186781e-005,3,9.687384e-001,1.825000e+000,,,,,,,,,,,,,,,,,,0,5.000000e+000,1.000000e+000,4,4,7.159948e-003,0,,0,
1611852635.473,,1.000000e+002,3.251042e+000,3.902034e-004,2.730733e-008,3.664057e-002,4.469712e-005,3,9.700368e-001,1.825000e+000,,,,,,,,,,,,,,,,,,0,5.000000e+000,1.000000e+000,4,4,7.155895e-003,0,,0,
1611852851.144,,1.000000e+002,3.523457e+000,3.858946e-004,1.327415e-007,3.758423e-002,2.308258e-005,3,9.713058e-001,1.825000e+000,,,,,,,,,,,,,,,,,,0,5.000000e+000,1.000000e+000,4,4,2.747321e-002,0,,0,
1611853071.946,,1.000000e+002,3.762651e+000,3.824989e-004,5.906853e-008,3.835635e-002,1.768060e-005,3,9.722279e-001,1.825000e+000,,,,,,,,,,,,,,,,,,0,5.000000e+000,1.000000e+000,4,4,1.330209e-002,0,,0,
1611853336.195,,1.000000e+002,4.008170e+000,3.793287e-004,5.731744e-008,3.904106e-002,2.512624e-005,3,9.730888e-001,1.825000e+000,,,,,,,,,,,,,,,,,,0,5.000000e+000,1.000000e+000,4,4,1.304007e-002,0,,0,
1611853668.538,,1.000000e+002,4.261484e+000,3.762923e-004,7.645755e-008,3.968390e-002,3.000306e-005,3,9.738404e-001,1.825000e+000,,,,,,,,,,,,,,,,,,0,5.000000e+000,1.000000e+000,4,4,2.158213e-002,0,,0,
1611853996.326,,1.000000e+002,4.505345e+000,3.737582e-004,5.663743e-009,4.026234e-002,3.243380e-005,3,9.744322e-001,1.825000e+000,,,,,,,,,,,,,,,,,,0,5.000000e+000,1.000000e+000,4,4,7.247925e-003,0,,0,
1611854151.468,,1.000000e+002,4.754398e+000,3.715589e-004,2.977619e-008,4.061644e-002,6.484284e-006,3,9.749052e-001,1.825000e+000,,,,,,,,,,,,,,,,,,0,5.000000e+000,1.000000e+000,4,4,5.791187e-003,0,,0,
1611854307.625,,1.000000e+002,5.003821e+000,3.692724e-004,6.218442e-008,4.107575e-002,2.400976e-005,3,9.754476e-001,1.825000e+000,,,,,,,,,,,,,,,,,,0,5.000000e+000,1.000000e+000,4,4,6.668091e-003,0,,0,
1611854460.708,,1.000000e+002,5.253979e+000,3.670261e-004,3.189859e-008,4.154429e-002,7.956639e-005,3,9.759008e-001,1.825000e+000,,,,,,,,,,,,,,,,,,0,5.000000e+000,1.000000e+000,4,4,7.668018e-003,0,,0,
1611854613.198,,1.000000e+002,5.503528e+000,3.650381e-004,2.234046e-008,4.192114e-002,2.954817e-005,3,9.763045e-001,1.825000e+000,,,,,,,,,,,,,,,,,,0,5.000000e+000,1.000000e+000,4,4,5.043030e-003,0,,0,
1611854766.219,,1.000000e+002,5.753787e+000,3.631451e-004,1.740227e-008,4.230181e-002,1.952085e-005,3,9.766515e-001,1.825000e+000,,,,,,,,,,,,,,,,,,0,5.000000e+000,1.000000e+000,4,4,5.891800e-003,0,,0,
1611854919.957,,1.000000e+002,6.002686e+000,3.613938e-004,2.544122e-008,4.265337e-002,3.108570e-005,3,9.770353e-001,1.825000e+000,,,,,,,,,,,,,,,,,,0,5.000000e+000,1.000000e+000,4,4,3.885746e-003,0,,0,
1611855025.834,,1.000000e+002,6.502006e+000,3.584185e-004,6.654453e-009,4.327084e-002,2.974347e-005,3,9.776868e-001,1.825000e+000,,,,,,,,,,,,,,,,,,0,5.000000e+000,1.000000e+000,4,4,3.784657e-003,0,,0,
1611855179.339,,1.000000e+002,7.006654e+000,3.558472e-004,6.856559e-008,4.388751e-002,3.836853e-005,3,9.781644e-001,1.825000e+000,,,,,,,,,,,,,,,,,,0,5.000000e+000,1.000000e+000,4,4,4.052591e-002,0,,0,
1611855333.685,,1.000000e+002,7.506955e+000,3.537723e-004,1.768593e-008,4.437859e-002,2.228111e-005,3,9.784830e-001,1.825000e+000,,,,,,,,,,,,,,,,,,0,5.000000e+000,1.000000e+000,4,4,1.645184e-002,0,,0,
1611855487.969,,1.000000e+002,8.003925e+000,3.520441e-004,1.606696e-008,4.479526e-002,1.996585e-005,3,9.788432e-001,1.825000e+000,,,,,,,,,,,,,,,,,,0,5.000000e+000,1.000000e+000,4,4,5.587578e-003,0,,0,
1611855642.160,,1.000000e+002,8.502860e+000,3.506741e-004,1.646613e-008,4.519157e-002,2.074065e-005,3,9.791300e-001,1.825000e+000,,,,,,,,,,,,,,,,,,0,5.000000e+000,1.000000e+000,4,4,2.806664e-003,0,,0,
1611855796.554,,1.000000e+002,9.002850e+000,3.496141e-004,9.771507e-009,4.560807e-002,2.576920e-005,3,9.793748e-001,1.825000e+000,,,,,,,,,,,,,,,,,,0,5.000000e+000,1.000000e+000,4,4,3.843307e-003,0,,0,
1611855951.165,,1.000000e+002,9.503215e+000,3.487989e-004,2.189426e-008,4.593396e-002,2.744617e-005,3,9.795525e-001,1.825000e+000,,,,,,,,,,,,,,,,,,0,5.000000e+000,1.000000e+000,4,4,3.263474e-003,0,,0,
1611856105.793,,1.000000e+002,1.000260e+001,3.482177e-004,2.582034e-008,4.621711e-002,1.605209e-005,3,9.797297e-001,1.825000e+000,,,,,,,,,,,,,,,,,,0,5.000000e+000,1.000000e+000,4,4,4.119873e-003,0,,0,
1611856260.186,,1.000000e+002,1.050845e+001,3.478710e-004,8.409194e-009,4.653590e-002,1.376867e-005,3,9.799201e-001,1.825000e+000,,,,,,,,,,,,,,,,,,0,5.000000e+000,1.000000e+000,4,4,2.619743e-003,0,,0,
1611856415.064,,1.000000e+002,1.101485e+001,3.477793e-004,7.714912e-009,4.679471e-002,1.826493e-005,3,9.800038e-001,1.825000e+000,,,,,,,,,,,,,,,,,,0,5.000000e+000,1.000000e+000,4,4,3.490448e-003,0,,0,
1611856569.675,,1.000000e+002,1.151982e+001,3.478740e-004,7.653441e-009,4.705606e-002,3.035962e-005,3,9.801180e-001,1.825000e+000,,,,,,,,,,,,,,,,,,0,5.000000e+000,1.000000e+000,4,4,3.550529e-003,0,,0,
1611856728.796,,1.000000e+002,1.200099e+001,3.481444e-004,6.093089e-009,4.726568e-002,2.478863e-005,3,9.801940e-001,1.825000e+000,,,,,,,,,,,,,,,,,,0,5.000000e+000,1.000000e+000,4,4,1.880646e-003,0,,0,
1611856884.968,,1.000000e+002,1.250461e+001,3.486171e-004,1.756810e-008,4.752516e-002,3.184303e-005,3,9.803266e-001,1.825000e+000,,,,,,,,,,,,,,,,,,0,5.000000e+000,1.000000e+000,4,4,1.639366e-003,0,,0,
1611857039.845,,1.000000e+002,1.300914e+001,3.492641e-004,8.627981e-009,4.772431e-002,3.352614e-005,3,9.803862e-001,1.825000e+000,,,,,,,,,,,,,,,,,,0,5.000000e+000,1.000000e+000,4,4,2.130508e-003,0,,0,
1611857193.427,,1.000000e+002,1.351427e+001,3.500859e-004,1.787553e-008,4.792213e-002,1.840596e-005,3,9.804409e-001,1.825000e+000,,,,,,,,,,,,,,,,,,0,5.000000e+000,1.000000e+000,4,4,4.869461e-003,0,,0,
1611857346.463,,1.000000e+002,1.401815e+001,3.510740e-004,8.135653e-009,4.810655e-002,1.248942e-005,3,9.804792e-001,1.825000e+000,,,,,,,,,,,,,,,,,,0,5.000000e+000,1.000000e+000,4,4,1.124954e-002,0,,0,
1611857498.953,,1.000000e+002,1.450028e+001,3.522288e-004,1.157594e-008,4.830771e-002,4.701277e-005,3,9.805312e-001,1.825000e+000,,,,,,,,,,,,,,,,,,0,5.000000e+000,1.000000e+000,4,4,4.509926e-003,0,,0,
1611857603.177,,1.000000e+002,1.499770e+001,3.535938e-004,7.421153e-009,4.847529e-002,3.637010e-005,3,9.806283e-001,1.825000e+000,,,,,,,,,,,,,,,,,,0,5.000000e+000,1.000000e+000,4,4,9.039879e-003,0,,0,
1611857757.539,,1.000000e+002,1.525105e+001,3.543929e-004,8.799037e-009,4.857548e-002,3.116637e-005,3,9.805920e-001,1.825000e+000,,,,,,,,,,,,,,,,,,0,5.000000e+000,1.000000e+000,4,4,3.740311e-003,0,,0,
1611857912.151,,1.000000e+002,1.550092e+001,3.552229e-004,9.304202e-009,4.866093e-002,2.095061e-005,3,9.806167e-001,1.825000e+000,,,,,,,,,,,,,,,,,,0,5.000000e+000,1.000000e+000,4,4,3.870010e-003,0,,0,
1611858066.810,,1.000000e+002,1.575119e+001,3.560983e-004,1.425544e-008,4.875471e-002,1.938684e-005,3,9.806129e-001,1.825000e+000,,,,,,,,,,,,,,,,,,0,5.000000e+000,1.000000e+000,4,4,4.650116e-003,0,,0,
1611858221.157,,1.000000e+002,1.600090e+001,3.570279e-004,1.994589e-008,4.882904e-002,2.939825e-005,3,9.806520e-001,1.825000e+000,,,,,,,,,,,,,,,,,,0,5.000000e+000,1.000000e+000,4,4,3.439903e-003,0,,0,
1611858374.973,,1.000000e+002,1.625117e+001,3.580034e-004,2.355143e-008,4.891497e-002,1.557158e-005,3,9.806516e-001,1.825000e+000,,,,,,,,,,,,,,,,,,0,5.000000e+000,1.000000e+000,4,4,3.540039e-003,0,,0,
1611858528.987,,1.000000e+002,1.650150e+001,3.590379e-004,2.872565e-008,4.900715e-002,8.974219e-006,3,9.806656e-001,1.825000e+000,,,,,,,,,,,,,,,,,,0,5.000000e+000,1.000000e+000,4,4,4.388809e-003,0,,0,
1611858683.028,,1.000000e+002,1.675160e+001,3.601271e-004,1.932378e-008,4.907855e-002,1.121409e-005,3,9.806451e-001,1.825000e+000,,,,,,,,,,,,,,,,,,0,5.000000e+000,1.000000e+000,4,4,4.520416e-003,0,,0,
1611858839.509,,1.000000e+002,1.700121e+001,3.612813e-004,1.471001e-008,4.916350e-002,2.232447e-005,3,9.806823e-001,1.825000e+000,,,,,,,,,,,,,,,,,,0,5.000000e+000,1.000000e+000,4,4,4.650116e-003,0,,0,
1611858997.256,,1.000000e+002,1.725132e+001,3.624700e-004,2.180289e-008,4.924597e-002,3.803090e-005,3,9.806978e-001,1.825000e+000,,,,,,,,,,,,,,,,,,0,5.000000e+000,1.000000e+000,4,4,4.789352e-003,0,,0,
1611859151.338,,1.000000e+002,1.750112e+001,3.637129e-004,2.278584e-008,4.928178e-002,1.802020e-005,3,9.807006e-001,1.825000e+000,,,,,,,,,,,,,,,,,,0,5.000000e+000,1.000000e+000,4,4,3.280640e-003,0,,0,
1611859305.950,,1.000000e+002,1.775070e+001,3.650003e-004,1.150289e-008,4.940346e-002,3.364166e-005,3,9.807014e-001,1.825000e+000,,,,,,,,,,,,,,,,,,0,5.000000e+000,1.000000e+000,4,4,4.230499e-003,0,,0,
1611859460.562,,1.000000e+002,1.800070e+001,3.663050e-004,2.241974e-008,4.949160e-002,5.518554e-005,3,9.806957e-001,1.825000e+000,,,,,,,,,,,,,,,,,,0,5.000000e+000,1.000000e+000,4,4,3.480911e-003,0,,0,
1611859615.704,,1.000000e+002,1.825052e+001,3.676311e-004,1.036253e-008,4.951664e-002,2.694467e-005,3,9.807221e-001,1.825000e+000,,,,,,,,,,,,,,,,,,0,5.000000e+000,1.000000e+000,4,4,3.570557e-003,0,,0,
1611859771.408,,1.000000e+002,1.850065e+001,3.689454e-004,2.404184e-008,4.956871e-002,5.092228e-005,3,9.807123e-001,1.825000e+000,,,,,,,,,,,,,,,,,,0,5.000000e+000,1.000000e+000,4,4,4.579544e-003,0,,0,
1611859925.754,,1.000000e+002,1.875084e+001,3.702239e-004,1.399265e-008,4.962292e-002,2.954308e-005,3,9.806921e-001,1.825000e+000,,,,,,,,,,,,,,,,,,0,5.000000e+000,1.000000e+000,4,4,2.819061e-003,0,,0,
1611860081.115,,1.000000e+002,1.900100e+001,3.714272e-004,1.987547e-008,4.968815e-002,5.044476e-005,3,9.807233e-001,1.825000e+000,,,,,,,,,,,,,,,,,,0,5.000000e+000,1.000000e+000,4,4,2.901077e-003,0,,0,
1611860236.289,,1.000000e+002,1.925084e+001,3.725552e-004,1.229975e-008,4.973518e-002,3.567086e-005,3,9.807060e-001,1.825000e+000,,,,,,,,,,,,,,,,,,0,5.000000e+000,1.000000e+000,4,4,1.991272e-003,0,,0,
1611860391.696,,1.000000e+002,1.950097e+001,3.735910e-004,1.553882e-008,4.981631e-002,6.119743e-005,3,9.807147e-001,1.825000e+000,,,,,,,,,,,,,,,,,,0,5.000000e+000,1.000000e+000,4,4,2.031326e-003,0,,0,
1611860546.791,,1.000000e+002,1.975043e+001,3.744854e-004,3.252513e-008,4.983573e-002,1.795199e-005,3,9.807501e-001,1.825000e+000,,,,,,,,,,,,,,,,,,0,5.000000e+000,1.000000e+000,4,4,2.599716e-003,0,,0,
1611860702.527,,1.000000e+002,2.000069e+001,3.753041e-004,3.362943e-008,4.989451e-002,1.956364e-005,3,9.807305e-001,1.825000e+000,,,,,,,,,,,,,,,,,,0,5.000000e+000,1.000000e+000,4,4,2.140045e-003,0,,0,
1611860857.404,,1.000000e+002,2.025059e+001,3.759770e-004,1.045844e-008,4.989157e-002,1.858785e-005,3,9.807541e-001,1.825000e+000,,,,,,,,,,,,,,,,,,0,5.000000e+000,1.000000e+000,4,4,1.649857e-003,0,,0,
1611861011.588,,1.000000e+002,2.050128e+001,3.765365e-004,2.044664e-008,4.996209e-002,3.333073e-005,3,9.807181e-001,1.825000e+000,,,,,,,,,,,,,,,,,,0,5.000000e+000,1.000000e+000,4,4,1.689911e-003,0,,0,
1611861167.438,,1.000000e+002,2.075059e+001,3.769881e-004,2.089552e-008,4.999693e-002,1.484131e-005,3,9.807617e-001,1.825000e+000,,,,,,,,,,,,,,,,,,0,5.000000e+000,1.000000e+000,4,4,1.720428e-003,0,,0,
1611861325.977,,1.000000e+002,2.100047e+001,3.773881e-004,1.109273e-008,5.004106e-002,5.300808e-005,3,9.807408e-001,1.825000e+000,,,,,,,,,,,,,,,,,,0,5.000000e+000,1.000000e+000,4,4,1.760483e-003,0,,0,
1611861480.620,,1.000000e+002,2.125069e+001,3.776733e-004,1.855929e-008,5.010815e-002,2.849582e-005,3,9.807457e-001,1.825000e+000,,,,,,,,,,,,,,,,,,0,5.000000e+000,1.000000e+000,4,4,1.199722e-003,0,,0,
1611861635.653,,1.000000e+002,2.150072e+001,3.778815e-004,6.431486e-009,5.014022e-002,1.632981e-005,3,9.807499e-001,1.825000e+000,,,,,,,,,,,,,,,,,,0,5.000000e+000,1.000000e+000,4,4,1.230240e-003,0,,0,
1611861790.109,,1.000000e+002,2.175133e+001,3.780620e-004,1.156153e-008,5.015706e-002,1.599644e-005,3,9.807490e-001,1.825000e+000,,,,,,,,,,,,,,,,,,0,5.000000e+000,1.000000e+000,4,4,1.260757e-003,0,,0,
1611861944.721,,1.000000e+002,2.200093e+001,3.781894e-004,1.132347e-008,5.020454e-002,2.742959e-005,3,9.807547e-001,1.825000e+000,,,,,,,,,,,,,,,,,,0,5.000000e+000,1.000000e+000,4,4,1.920700e-003,0,,0,
1611862100.191,,1.000000e+002,2.225083e+001,3.782854e-004,2.738459e-008,5.025347e-002,3.474421e-005,3,9.807727e-001,1.825000e+000,,,,,,,,,,,,,,,,,,0,5.000000e+000,1.000000e+000,4,4,1.310349e-003,0,,0,
1611862255.926,,1.000000e+002,2.250053e+001,3.783594e-004,7.871353e-009,5.029767e-002,3.435087e-005,3,9.807665e-001,1.825000e+000,,,,,,,,,,,,,,,,,,0,5.000000e+000,1.000000e+000,4,4,2.008438e-003,0,,0,
1611862410.538,,1.000000e+002,2.275019e+001,3.784018e-004,1.573039e-008,5.034889e-002,1.866969e-005,3,9.807730e-001,1.825000e+000,,,,,,,,,,,,,,,,,,0,5.000000e+000,1.000000e+000,4,4,2.740860e-003,0,,0,
1611862566.960,,1.000000e+002,2.300079e+001,3.784059e-004,1.129605e-008,5.040262e-002,1.479099e-005,3,9.807883e-001,1.825000e+000,,,,,,,,,,,,,,,,,,0,5.000000e+000,1.000000e+000,4,4,6.904602e-004,0,,0,
1611862722.367,,1.000000e+002,2.325096e+001,3.784111e-004,1.893157e-008,5.047955e-002,2.708086e-005,3,9.807783e-001,1.825000e+000,,,,,,,,,,,,,,,,,,0,5.000000e+000,1.000000e+000,4,4,1.428604e-003,0,,0,
1611862878.040,,1.000000e+002,2.350142e+001,3.783951e-004,1.393257e-008,5.052999e-002,4.170700e-005,3,9.808060e-001,1.825000e+000,,,,,,,,,,,,,,,,,,0,5.000000e+000,1.000000e+000,4,4,1.449585e-003,0,,0,
1611863033.681,,1.000000e+002,2.375114e+001,3.783448e-004,1.284216e-008,5.059382e-002,1.578740e-005,3,9.807497e-001,1.825000e+000,,,,,,,,,,,,,,,,,,0,5.000000e+000,1.000000e+000,4,4,3.709793e-003,0,,0,
1611863188.855,,1.000000e+002,2.400094e+001,3.782868e-004,1.289222e-008,5.064255e-002,4.974699e-005,3,9.807687e-001,1.825000e+000,,,,,,,,,,,,,,,,,,0,5.000000e+000,1.000000e+000,4,4,2.269745e-003,0,,0,
1611863344.044,,1.000000e+002,2.425051e+001,3.782213e-004,2.730831e-008,5.068590e-002,4.158975e-005,3,9.808205e-001,1.825000e+000,,,,,,,,,,,,,,,,,,0,5.000000e+000,1.000000e+000,4,4,3.078461e-003,0,,0,
1611863498.749,,1.000000e+002,2.450175e+001,3.781493e-004,7.866330e-009,5.070101e-002,2.359982e-005,3,9.807801e-001,1.825000e+000,,,,,,,,,,,,,,,,,,0,5.000000e+000,1.000000e+000,4,4,4.720688e-003,0,,0,
1611863654.157,,1.000000e+002,2.475072e+001,3.780359e-004,1.072257e-008,5.079133e-002,1.317130e-005,3,9.807847e-001,1.825000e+000,,,,,,,,,,,,,,,,,,0,5.000000e+000,1.000000e+000,4,4,4.009247e-003,0,,0,
1611863809.876,,1.000000e+002,2.500070e+001,3.779359e-004,8.677157e-009,5.084340e-002,3.913536e-005,3,9.807767e-001,1.825000e+000,,,,,,,,,,,,,,,,,,0,5.000000e+000,1.000000e+000,4,4,4.089355e-003,0,,0,
1611865140.387,,1.000000e+002,2.600109e+001,3.773663e-004,9.598559e-009,5.106854e-002,2.521820e-005,3,9.807914e-001,1.825000e+000,,,,,,,,,,,,,,,,,,0,5.000000e+000,1.000000e+000,4,4,1.760483e-003,0,,0,
1611865298.712,,1.000000e+002,2.801020e+001,3.757411e-004,1.352701e-008,5.137797e-002,2.733156e-005,3,9.808250e-001,1.825000e+000,,,,,,,,,,,,,,,,,,0,5.000000e+000,1.000000e+000,4,4,6.078720e-003,0,,0,
1611865460.515,,1.000000e+002,3.001192e+001,3.737040e-004,2.115630e-008,5.169038e-002,3.028110e-005,3,9.808100e-001,1.825000e+000,,,,,,,,,,,,,,,,,,0,5.000000e+000,1.000000e+000,4,4,6.919861e-003,0,,0,
1611865622.287,,1.000000e+002,3.201499e+001,3.713114e-004,2.851583e-008,5.194112e-002,4.678822e-005,3,9.808210e-001,1.825000e+000,,,,,,,,,,,,,,,,,,0,5.000000e+000,1.000000e+000,4,4,7.812500e-003,0,,0,
1611865785.916,,1.000000e+002,3.401780e+001,3.685854e-004,2.806600e-008,5.230538e-002,4.845485e-005,3,9.808114e-001,1.825000e+000,,,,,,,,,,,,,,,,,,0,5.000000e+000,1.000000e+000,4,4,1.168060e-002,0,,0,
1611865953.788,,1.000000e+002,3.602113e+001,3.656661e-004,2.175887e-008,5.270959e-002,4.711657e-005,3,9.808072e-001,1.825000e+000,,,,,,,,,,,,,,,,,,0,5.000000e+000,1.000000e+000,4,4,1.303864e-002,0,,0,
1611866122.455,,1.000000e+002,3.802266e+001,3.624619e-004,4.044213e-008,5.312591e-002,3.997524e-005,3,9.808406e-001,1.825000e+000,,,,,,,,,,,,,,,,,,0,5.000000e+000,1.000000e+000,4,4,1.808167e-002,0,,0,
1611866293.775,,1.000000e+002,4.002589e+001,3.591212e-004,6.290556e-008,5.344303e-002,3.824223e-005,3,9.808849e-001,1.825000e+000,,,,,,,,,,,,,,,,,,0,5.000000e+000,1.000000e+000,4,4,1.989746e-002,0,,0,
1611866466.951,,1.000000e+002,4.203153e+001,3.556060e-004,4.494407e-008,5.382494e-002,1.274829e-005,3,9.808762e-001,1.825000e+000,,,,,,,,,,,,,,,,,,0,5.000000e+000,1.000000e+000,4,4,2.400970e-002,0,,0,
1611866639.066,,1.000000e+002,4.403497e+001,3.519738e-004,2.302706e-008,5.416349e-002,2.749592e-005,3,9.808491e-001,1.825000e+000,,,,,,,,,,,,,,,,,,0,5.000000e+000,1.000000e+000,4,4,2.098083e-002,0,,0,
1611866810.432,,1.000000e+002,4.604056e+001,3.482074e-004,4.043157e-008,5.460349e-002,3.549641e-005,3,9.808666e-001,1.825000e+000,,,,,,,,,,,,,,,,,,0,5.000000e+000,1.000000e+000,4,4,2.183151e-002,0,,0,
1611866982.812,,1.000000e+002,4.804287e+001,3.443886e-004,4.067524e-008,5.498329e-002,3.151443e-005,3,9.808267e-001,1.825000e+000,,,,,,,,,,,,,,,,,,0,5.000000e+000,1.000000e+000,4,4,2.820969e-002,0,,0,
1611867151.480,,1.000000e+002,5.004980e+001,3.405385e-004,2.027108e-008,5.540299e-002,3.095268e-005,3,9.808248e-001,1.825000e+000,,,,,,,,,,,,,,,,,,0,5.000000e+000,1.000000e+000,4,4,2.799225e-002,0,,0,
1611867345.326,,1.000000e+002,5.505335e+001,3.307005e-004,3.076732e-008,5.636604e-002,1.127480e-005,3,9.808717e-001,1.825000e+000,,,,,,,,,,,,,,,,,,0,5.000000e+000,1.000000e+000,4,4,3.197098e-002,0,,0,
1611867547.409,,1.000000e+002,6.007858e+001,3.207950e-004,2.872589e-008,5.742019e-002,4.548666e-005,3,9.808583e-001,1.825000e+000,,,,,,,,,,,,,,,,,,0,5.000000e+000,1.000000e+000,4,4,4.132080e-002,0,,0,
1611867752.190,,1.000000e+002,6.509068e+001,3.110964e-004,4.579146e-009,5.821617e-002,1.212626e-004,3,9.806073e-001,1.825000e+000,,,,,,,,,,,,,,,,,,0,5.000000e+000,1.000000e+000,4,4,5.204010e-002,0,,0,
1611867959.842,,1.000000e+002,7.010584e+001,3.015493e-004,2.137544e-008,5.906812e-002,5.184500e-005,3,9.805055e-001,1.825000e+000,,,,,,,,,,,,,,,,,,0,5.000000e+000,1.000000e+000,4,4,5.754089e-002,0,,0,
1611868168.602,,1.000000e+002,7.512129e+001,2.922505e-004,1.628964e-008,6.015258e-002,8.690451e-005,3,9.806179e-001,1.825000e+000,,,,,,,,,,,,,,,,,,0,5.000000e+000,1.000000e+000,4,4,7.109070e-002,0,,0,
1611868378.110,,1.000000e+002,8.013232e+001,2.833817e-004,1.855086e-008,6.126199e-002,2.665000e-005,3,9.806914e-001,1.825000e+000,,,,,,,,,,,,,,,,,,0,5.000000e+000,1.000000e+000,4,4,7.739258e-002,0,,0,
1611868588.149,,1.000000e+002,8.514762e+001,2.748141e-004,1.916053e-008,6.238939e-002,4.278875e-005,3,9.806467e-001,1.825000e+000,,,,,,,,,,,,,,,,,,0,5.000000e+000,1.000000e+000,4,4,6.990051e-002,0,,0,
1611868799.202,,1.000000e+002,9.016214e+001,2.665692e-004,1.501886e-008,6.354742e-002,4.807293e-005,3,9.806646e-001,1.825000e+000,,,,,,,,,,,,,,,,,,0,5.000000e+000,1.000000e+000,4,4,9.268951e-002,0,,0,
1611869011.050,,1.000000e+002,9.517228e+001,2.586887e-004,2.063706e-009,6.479254e-002,3.448639e-005,3,9.806846e-001,1.825000e+000,,,,,,,,,,,,,,,,,,0,5.000000e+000,1.000000e+000,4,4,8.225250e-002,0,,0,
1611869222.883,,1.000000e+002,1.001857e+002,2.511988e-004,1.680816e-008,6.603499e-002,3.376745e-005,3,9.806236e-001,1.825000e+000,,,,,,,,,,,,,,,,,,0,5.000000e+000,1.000000e+000,4,4,1.088028e-001,0,,0,
1611869487.444,,1.000000e+002,1.102174e+002,2.371336e-004,1.471502e-008,6.850781e-002,2.089870e-005,3,9.806588e-001,1.825000e+000,,,,,,,,,,,,,,,,,,0,5.000000e+000,1.000000e+000,4,4,1.408005e-001,0,,0,
1611869750.257,,1.000000e+002,1.202478e+002,2.241415e-004,3.307665e-008,7.112080e-002,2.472495e-005,3,9.806508e-001,1.825000e+000,,,,,,,,,,,,,,,,,,0,5.000000e+000,1.000000e+000,4,4,1.532059e-001,0,,0,
1611870007.252,,1.000000e+002,1.302821e+002,2.124773e-004,3.593083e-008,7.388841e-002,3.759730e-005,3,9.805943e-001,1.825000e+000,,,,,,,,,,,,,,,,,,0,5.000000e+000,1.000000e+000,4,4,1.672058e-001,0,,0,
1611870261.876,,1.000000e+002,1.403067e+002,2.018283e-004,2.381244e-008,7.671481e-002,1.245946e-005,3,9.805437e-001,1.825000e+000,,,,,,,,,,,,,,,,,,0,5.000000e+000,1.000000e+000,4,4,1.840973e-001,0,,0,
1611870514.347,,1.000000e+002,1.503232e+002,1.921041e-004,3.565565e-008,7.964686e-002,4.122471e-005,3,9.805092e-001,1.825000e+000,,,,,,,,,,,,,,,,,,0,5.000000e+000,1.000000e+000,4,4,2.052002e-001,0,,0,
1611870765.523,,1.000000e+002,1.603482e+002,1.831882e-004,2.219932e-008,8.272219e-002,3.105517e-005,3,9.804845e-001,1.825000e+000,,,,,,,,,,,,,,,,,,0,5.000000e+000,1.000000e+000,4,4,2.046967e-001,0,,0,
1611871013.282,,1.000000e+002,1.703703e+002,1.749754e-004,2.740809e-008,8.594337e-002,5.604715e-005,3,9.803717e-001,1.825000e+000,,,,,,,,,,,,,,,,,,0,5.000000e+000,1.000000e+000,4,4,2.241974e-001,0,,0,
1611871260.184,,1.000000e+002,1.803901e+002,1.674252e-004,2.824740e-008,8.931136e-002,6.629199e-005,3,9.803644e-001,1.825000e+000,,,,,,,,,,,,,,,,,,0,5.000000e+000,1.000000e+000,4,4,2.368927e-001,0,,0,
1611871504.168,,1.000000e+002,1.904085e+002,1.604550e-004,2.238132e-008,9.305337e-002,1.339303e-004,3,9.802881e-001,1.825000e+000,,,,,,,,,,,,,,,,,,0,5.000000e+000,1.000000e+000,4,4,2.714996e-001,0,,0,
1611871747.045,,1.000000e+002,2.004172e+002,1.540098e-004,3.859800e-008,9.703634e-002,9.946614e-005,3,9.802507e-001,1.825000e+000,,,,,,,,,,,,,,,,,,0,5.000000e+000,1.000000e+000,4,4,2.577057e-001,0,,0,
1611871987.582,,1.000000e+002,2.104494e+002,1.480307e-004,3.034003e-008,1.011050e-001,7.978287e-005,3,9.801612e-001,1.825000e+000,,,,,,,,,,,,,,,,,,0,5.000000e+000,1.000000e+000,4,4,2.937012e-001,0,,0,
1611872237.120,,1.000000e+002,2.203769e+002,1.424804e-004,5.182973e-008,1.051800e-001,3.731105e-005,3,9.802805e-001,1.825000e+000,,,,,,,,,,,,,,,,,,0,5.000000e+000,1.000000e+000,4,4,3.121033e-001,0,,0,
1611872477.345,,1.000000e+002,2.304646e+002,1.372458e-004,2.668375e-008,1.098188e-001,1.740078e-004,3,9.801120e-001,1.825000e+000,,,,,,,,,,,,,,,,,,0,5.000000e+000,1.000000e+000,4,4,3.419037e-001,0,,0,
1611872716.774,,1.000000e+002,2.404776e+002,1.323829e-004,3.505286e-008,1.141569e-001,3.401422e-005,3,9.799844e-001,1.825000e+000,,,,,,,,,,,,,,,,,,0,5.000000e+000,1.000000e+000,4,4,3.604126e-001,0,,0,
1611872955.408,,1.000000e+002,2.504969e+002,1.278167e-004,3.427230e-008,1.184200e-001,3.023985e-005,3,9.799302e-001,1.825000e+000,,,,,,,,,,,,,,,,,,0,5.000000e+000,1.000000e+000,4,4,3.916016e-001,0,,0,
1611873195.633,,1.000000e+002,2.604958e+002,1.235363e-004,3.900964e-008,1.227875e-001,4.931420e-005,3,9.797573e-001,1.825000e+000,,,,,,,,,,,,,,,,,,0,5.000000e+000,1.000000e+000,4,4,4.094849e-001,0,,0,
1611873433.034,,1.000000e+002,2.705265e+002,1.194735e-004,2.119745e-008,1.272730e-001,6.879985e-005,3,9.795815e-001,1.825000e+000,,,,,,,,,,,,,,,,,,0,5.000000e+000,1.000000e+000,4,4,4.284058e-001,0,,0,
1611873671.667,,1.000000e+002,2.805125e+002,1.156836e-004,2.329586e-008,1.320738e-001,5.682314e-005,3,9.794400e-001,1.825000e+000,,,,,,,,,,,,,,,,,,0,5.000000e+000,1.000000e+000,4,4,3.945923e-001,0,,0,
1611873910.301,,1.000000e+002,2.905051e+002,1.121019e-004,2.397877e-008,1.377372e-001,3.805842e-005,3,9.792037e-001,1.825000e+000,,,,,,,,,,,,,,,,,,0,5.000000e+000,1.000000e+000,4,4,4.161072e-001,0,,0,
1611874151.353,,1.000000e+002,3.005025e+002,1.087191e-004,1.005129e-008,1.438841e-001,7.071876e-005,3,9.789715e-001,1.825000e+000,,,,,,,,,,,,,,,,,,0,5.000000e+000,1.000000e+000,4,4,4.078979e-001,0,,0,