File: Analysis_of_CrCl2pym/MPMS/MPMS_CrCl2pym_FC.rso.dat
[Header]
TITLE,MPMS RSO Measurement
BYAPP,MPMS Measurement,1.1,Summary
FILEOPENTIME, 1611874962.024000 1/28/2021, 11:02:42 PM

INFO, APPNAME, MPMS MultiVu Application, Revision 1.61,  Build 082

INFO, NAME, sicogi_CrCl2pym
INFO, WEIGHT, 26.600
INFO, AREA, 1.000
INFO, LENGTH, 1.000
INFO, SHAPE, 0
INFO, COMMENT, eicosane 44.5
INFO, SEQUENCE FILE: JP_ZFC_FC_MH_280121.seq


INFO, BACKGROUND DATA FILE:, None


STARTUPAXIS,X,4,LINEAR,AUTO,0.000000,0.000000
STARTUPAXIS,Y1,5,LINEAR,AUTO,0.000000,0.000000


STARTUPGROUP,Longitudinal
FIELDGROUP,Longitudinal,1,2,3,4,5,6,7,8,9,10,11,19,20,21,22,23,35
FIELDGROUP,Transverse,1,2,3,4,12,13,14,15,16,17,18,24,25,26,27,28,35

PLOT_APPEARANCE,ALL,HORZ_GRID_ON,VERT_GRID_ON,MARKERS_AND_LINES

[Data]
Time,Comment,Field (Oe),Temperature (K),Long Moment (emu),Long Scan Std Dev,Long Offset (cm),Long Offset Std Dev,Long Algorithm,Long Reg Fit,Long Reg Factor,Trans Moment (emu),Trans Scan Std Dev,Trans Offset (cm),Trans Offset Std Dev,Trans Algorithm,Trans Reg Fit,Trans Reg Factor,Long Moment [w/o ABS] (emu),Long Scan Std Dev [w/o ABS],Long Offset [w/o ABS] (cm),Long Offset Std Dev [w/o ABS],Long Reg Fit [w/o ABS],Trans Moment [w/o ABS] (emu),Trans Scan Std Dev [w/o ABS],Trans Offset [w/o ABS] (cm),Trans Offset Std Dev [w/o ABS],Trans Reg Fit [w/o ABS],RSO Position (deg),Amplitude (cm),Frequency,Cycles to Average,Scans per Measurement,Delta Temp (K),Error,EC Comp. Running,Using ABS,
1611874962.024,,1.000000e+002,3.000010e+002,1.088772e-004,1.215501e-008,1.457116e-001,4.019094e-005,3,9.788603e-001,1.825000e+000,,,,,,,,,,,,,,,,,,0,5.000000e+000,1.000000e+000,4,4,1.980591e-002,0,,0,
1611875471.287,,1.000000e+002,2.902695e+002,1.121958e-004,2.746548e-008,1.482146e-001,8.637656e-005,3,9.789783e-001,1.825000e+000,,,,,,,,,,,,,,,,,,0,5.000000e+000,1.000000e+000,4,4,5.541992e-002,0,,0,
1611875715.162,,1.000000e+002,2.794916e+002,1.161513e-004,2.912583e-008,1.421555e-001,4.795058e-005,3,9.791582e-001,1.825000e+000,,,,,,,,,,,,,,,,,,0,5.000000e+000,1.000000e+000,4,4,3.914795e-001,0,,0,
1611875934.701,,1.000000e+002,2.695627e+002,1.199967e-004,2.003468e-008,1.367936e-001,7.907751e-005,3,9.793079e-001,1.825000e+000,,,,,,,,,,,,,,,,,,0,5.000000e+000,1.000000e+000,4,4,3.147888e-001,0,,0,
1611876154.349,,1.000000e+002,2.595550e+002,1.240767e-004,1.891608e-008,1.315128e-001,8.376024e-005,3,9.795069e-001,1.825000e+000,,,,,,,,,,,,,,,,,,0,5.000000e+000,1.000000e+000,4,4,2.829895e-001,0,,0,
1611876375.230,,1.000000e+002,2.495886e+002,1.283589e-004,1.801233e-008,1.265619e-001,4.631385e-005,3,9.796238e-001,1.825000e+000,,,,,,,,,,,,,,,,,,0,5.000000e+000,1.000000e+000,4,4,3.016052e-001,0,,0,
1611876596.501,,1.000000e+002,2.395955e+002,1.329486e-004,1.710330e-008,1.215161e-001,6.536388e-005,3,9.797974e-001,1.825000e+000,,,,,,,,,,,,,,,,,,0,5.000000e+000,1.000000e+000,4,4,2.651978e-001,0,,0,
1611876818.365,,1.000000e+002,2.295970e+002,1.378346e-004,2.610190e-008,1.168052e-001,3.475605e-005,3,9.799690e-001,1.825000e+000,,,,,,,,,,,,,,,,,,0,5.000000e+000,1.000000e+000,4,4,2.543945e-001,0,,0,
1611877043.052,,1.000000e+002,2.196129e+002,1.430407e-004,3.153652e-008,1.122038e-001,8.818846e-005,3,9.801376e-001,1.825000e+000,,,,,,,,,,,,,,,,,,0,5.000000e+000,1.000000e+000,4,4,2.738037e-001,0,,0,
1611877268.800,,1.000000e+002,2.096126e+002,1.486255e-004,1.642369e-008,1.078867e-001,3.773722e-005,3,9.802333e-001,1.825000e+000,,,,,,,,,,,,,,,,,,0,5.000000e+000,1.000000e+000,4,4,2.584076e-001,0,,0,
1611877496.311,,1.000000e+002,1.996238e+002,1.546365e-004,1.729892e-008,1.036482e-001,4.593778e-005,3,9.803319e-001,1.825000e+000,,,,,,,,,,,,,,,,,,0,5.000000e+000,1.000000e+000,4,4,2.471008e-001,0,,0,
1611877725.803,,1.000000e+002,1.896442e+002,1.610993e-004,1.886403e-008,9.951661e-002,5.017151e-005,3,9.803656e-001,1.825000e+000,,,,,,,,,,,,,,,,,,0,5.000000e+000,1.000000e+000,4,4,2.269897e-001,0,,0,
1611877957.884,,1.000000e+002,1.796646e+002,1.680814e-004,2.296293e-008,9.554105e-002,1.784119e-005,3,9.804473e-001,1.825000e+000,,,,,,,,,,,,,,,,,,0,5.000000e+000,1.000000e+000,4,4,2.315063e-001,0,,0,
1611878196.814,,1.000000e+002,1.697130e+002,1.756308e-004,2.703555e-008,9.173939e-002,3.153103e-005,3,9.804409e-001,1.825000e+000,,,,,,,,,,,,,,,,,,0,5.000000e+000,1.000000e+000,4,4,2.503052e-001,0,,0,
1611878441.547,,1.000000e+002,1.597489e+002,1.838442e-004,1.661296e-008,8.819876e-002,6.046618e-005,3,9.804670e-001,1.825000e+000,,,,,,,,,,,,,,,,,,0,5.000000e+000,1.000000e+000,4,4,2.581024e-001,0,,0,
1611878694.502,,1.000000e+002,1.498258e+002,1.927520e-004,7.224651e-009,8.483414e-002,1.704029e-005,3,9.804693e-001,1.825000e+000,,,,,,,,,,,,,,,,,,0,5.000000e+000,1.000000e+000,4,4,2.474976e-001,0,,0,
1611878953.291,,1.000000e+002,1.399064e+002,2.024288e-004,1.192328e-008,8.169884e-002,4.168610e-005,3,9.804794e-001,1.825000e+000,,,,,,,,,,,,,,,,,,0,5.000000e+000,1.000000e+000,4,4,2.001038e-001,0,,0,
1611879226.354,,1.000000e+002,1.300256e+002,2.129814e-004,3.863639e-008,7.860753e-002,2.137009e-005,3,9.805049e-001,1.825000e+000,,,,,,,,,,,,,,,,,,0,5.000000e+000,1.000000e+000,4,4,1.296082e-001,0,,0,
1611879490.290,,1.000000e+002,1.200018e+002,2.246912e-004,2.488364e-008,7.583753e-002,4.282233e-005,3,9.805290e-001,1.825000e+000,,,,,,,,,,,,,,,,,,0,5.000000e+000,1.000000e+000,4,4,1.461945e-001,0,,0,
1611879889.370,,1.000000e+002,1.100709e+002,2.371887e-004,4.545720e-008,7.291870e-002,6.370662e-005,3,9.805024e-001,1.825000e+000,,,,,,,,,,,,,,,,,,0,5.000000e+000,1.000000e+000,4,4,2.159882e-002,0,,0,
1611880198.142,,1.000000e+002,9.995197e+001,2.515504e-004,4.506176e-008,7.047119e-002,9.597129e-005,3,9.804647e-001,1.825000e+000,,,,,,,,,,,,,,,,,,0,5.000000e+000,1.000000e+000,4,4,1.332474e-001,0,,0,
1611880420.536,,1.000000e+002,9.494950e+001,2.590953e-004,7.905937e-008,6.966652e-002,5.259887e-005,3,9.804854e-001,1.825000e+000,,,,,,,,,,,,,,,,,,0,5.000000e+000,1.000000e+000,4,4,2.046509e-001,0,,0,
1611880638.062,,1.000000e+002,8.995206e+001,2.669930e-004,7.942569e-008,6.837617e-002,4.985495e-005,3,9.805062e-001,1.825000e+000,,,,,,,,,,,,,,,,,,0,5.000000e+000,1.000000e+000,4,4,1.955109e-001,0,,0,
1611880976.365,,1.000000e+002,8.507072e+001,2.747977e-004,3.568912e-008,6.693008e-002,2.878820e-005,3,9.805489e-001,1.825000e+000,,,,,,,,,,,,,,,,,,0,5.000000e+000,1.000000e+000,4,4,2.160645e-002,0,,0,
1611881310.580,,1.000000e+002,8.007013e+001,2.833647e-004,3.526554e-008,6.558971e-002,1.874226e-005,3,9.805466e-001,1.825000e+000,,,,,,,,,,,,,,,,,,0,5.000000e+000,1.000000e+000,4,4,2.525330e-002,0,,0,
1611881631.956,,1.000000e+002,7.507002e+001,2.922118e-004,3.244620e-008,6.427627e-002,4.614769e-005,3,9.805509e-001,1.825000e+000,,,,,,,,,,,,,,,,,,0,5.000000e+000,1.000000e+000,4,4,2.892303e-002,0,,0,
1611881939.542,,1.000000e+002,7.007019e+001,3.015885e-004,2.232723e-008,6.295873e-002,3.462329e-005,3,9.805553e-001,1.825000e+000,,,,,,,,,,,,,,,,,,0,5.000000e+000,1.000000e+000,4,4,3.221130e-002,0,,0,
1611882171.483,,1.000000e+002,6.510519e+001,3.111413e-004,2.950321e-009,6.187251e-002,2.430810e-005,3,9.805700e-001,1.825000e+000,,,,,,,,,,,,,,,,,,0,5.000000e+000,1.000000e+000,4,4,1.202393e-002,0,,0,
1611882395.281,,1.000000e+002,6.009859e+001,3.208388e-004,2.279536e-008,6.079756e-002,5.798853e-005,3,9.805674e-001,1.825000e+000,,,,,,,,,,,,,,,,,,0,5.000000e+000,1.000000e+000,4,4,8.609772e-003,0,,0,
1611882656.722,,1.000000e+002,5.505843e+001,3.307092e-004,4.447410e-008,5.963817e-002,3.234841e-005,3,9.805334e-001,1.825000e+000,,,,,,,,,,,,,,,,,,0,5.000000e+000,1.000000e+000,4,4,3.052139e-002,0,,0,
1611882964.853,,1.000000e+002,5.001437e+001,3.406401e-004,2.216131e-008,5.851244e-002,6.497713e-005,3,9.805379e-001,1.825000e+000,,,,,,,,,,,,,,,,,,0,5.000000e+000,1.000000e+000,4,4,7.301331e-003,0,,0,
1611883159.464,,1.000000e+002,4.806616e+001,3.444126e-004,6.607424e-009,5.805444e-002,4.027345e-005,3,9.805602e-001,1.825000e+000,,,,,,,,,,,,,,,,,,0,5.000000e+000,1.000000e+000,4,4,2.146149e-002,0,,0,
1611883360.470,,1.000000e+002,4.606773e+001,3.482096e-004,1.741433e-008,5.762323e-002,5.047116e-005,3,9.805762e-001,1.825000e+000,,,,,,,,,,,,,,,,,,0,5.000000e+000,1.000000e+000,4,4,3.226089e-002,0,,0,
1611883564.113,,1.000000e+002,4.405906e+001,3.519925e-004,7.004577e-009,5.722325e-002,2.339754e-005,3,9.805348e-001,1.825000e+000,,,,,,,,,,,,,,,,,,0,5.000000e+000,1.000000e+000,4,4,3.437805e-002,0,,0,
1611883768.036,,1.000000e+002,4.205582e+001,3.556935e-004,3.000221e-008,5.684701e-002,1.396289e-005,3,9.805256e-001,1.825000e+000,,,,,,,,,,,,,,,,,,0,5.000000e+000,1.000000e+000,4,4,3.231812e-002,0,,0,
1611883976.500,,1.000000e+002,4.004819e+001,3.592456e-004,4.296368e-008,5.652880e-002,2.509364e-005,3,9.805598e-001,1.825000e+000,,,,,,,,,,,,,,,,,,0,5.000000e+000,1.000000e+000,4,4,2.947998e-002,0,,0,
1611884187.552,,1.000000e+002,3.804202e+001,3.626281e-004,5.065808e-008,5.628093e-002,4.642010e-006,3,9.805370e-001,1.825000e+000,,,,,,,,,,,,,,,,,,0,5.000000e+000,1.000000e+000,4,4,2.244949e-002,0,,0,
1611884405.500,,1.000000e+002,3.603642e+001,3.658584e-004,3.576341e-008,5.584742e-002,2.439174e-005,3,9.805648e-001,1.825000e+000,,,,,,,,,,,,,,,,,,0,5.000000e+000,1.000000e+000,4,4,2.774048e-002,0,,0,
1611884621.857,,1.000000e+002,3.403224e+001,3.688119e-004,2.852431e-008,5.548314e-002,3.351346e-005,3,9.805454e-001,1.825000e+000,,,,,,,,,,,,,,,,,,0,5.000000e+000,1.000000e+000,4,4,2.193832e-002,0,,0,
1611884841.958,,1.000000e+002,3.202640e+001,3.715088e-004,1.933154e-008,5.508618e-002,9.194086e-006,3,9.805560e-001,1.825000e+000,,,,,,,,,,,,,,,,,,0,5.000000e+000,1.000000e+000,4,4,1.565933e-002,0,,0,
1611885063.400,,1.000000e+002,3.002146e+001,3.739604e-004,1.503835e-008,5.471543e-002,4.329163e-005,3,9.805195e-001,1.825000e+000,,,,,,,,,,,,,,,,,,0,5.000000e+000,1.000000e+000,4,4,1.619911e-002,0,,0,
1611885285.326,,1.000000e+002,2.801804e+001,3.760036e-004,2.191529e-008,5.436867e-002,4.849728e-005,3,9.805265e-001,1.825000e+000,,,,,,,,,,,,,,,,,,0,5.000000e+000,1.000000e+000,4,4,1.114845e-002,0,,0,
1611885499.577,,1.000000e+002,2.600692e+001,3.776666e-004,1.401694e-008,5.421984e-002,9.610716e-005,3,9.805528e-001,1.825000e+000,,,,,,,,,,,,,,,,,,0,5.000000e+000,1.000000e+000,4,4,6.158829e-003,0,,0,
1611885688.540,,1.000000e+002,2.498559e+001,3.782256e-004,1.744527e-008,5.434540e-002,1.372413e-004,3,9.805577e-001,1.825000e+000,,,,,,,,,,,,,,,,,,0,5.000000e+000,1.000000e+000,4,4,3.020096e-002,0,,0,
1611885907.315,,1.000000e+002,2.477500e+001,3.783336e-004,2.171194e-008,5.452181e-002,4.303604e-005,3,9.805295e-001,1.825000e+000,,,,,,,,,,,,,,,,,,0,5.000000e+000,1.000000e+000,4,4,3.616142e-002,0,,0,
1611886185.198,,1.000000e+002,2.452430e+001,3.784454e-004,1.847582e-008,5.452934e-002,2.125382e-005,3,9.805447e-001,1.825000e+000,,,,,,,,,,,,,,,,,,0,5.000000e+000,1.000000e+000,4,4,2.758980e-002,0,,0,
1611886459.696,,1.000000e+002,2.427311e+001,3.785271e-004,1.066020e-008,5.457035e-002,9.291876e-005,3,9.805328e-001,1.825000e+000,,,,,,,,,,,,,,,,,,0,5.000000e+000,1.000000e+000,4,4,2.705956e-002,0,,0,
1611886736.004,,1.000000e+002,2.402159e+001,3.786070e-004,2.637326e-008,5.470286e-002,4.435684e-005,3,9.805634e-001,1.825000e+000,,,,,,,,,,,,,,,,,,0,5.000000e+000,1.000000e+000,4,4,2.502060e-002,0,,0,
1611887012.140,,1.000000e+002,2.376860e+001,3.786988e-004,2.807452e-008,5.469368e-002,5.420309e-005,3,9.805962e-001,1.825000e+000,,,,,,,,,,,,,,,,,,0,5.000000e+000,1.000000e+000,4,4,2.750015e-002,0,,0,
1611887283.425,,1.000000e+002,2.351972e+001,3.787341e-004,2.105515e-008,5.468630e-002,1.966418e-005,3,9.805837e-001,1.825000e+000,,,,,,,,,,,,,,,,,,0,5.000000e+000,1.000000e+000,4,4,2.622986e-002,0,,0,
1611887557.486,,1.000000e+002,2.326845e+001,3.787358e-004,9.888866e-009,5.472173e-002,1.346238e-005,3,9.805494e-001,1.825000e+000,,,,,,,,,,,,,,,,,,0,5.000000e+000,1.000000e+000,4,4,2.642059e-002,0,,0,
1611887829.098,,1.000000e+002,2.301766e+001,3.787269e-004,1.418662e-008,5.471120e-002,4.716885e-005,3,9.805663e-001,1.825000e+000,,,,,,,,,,,,,,,,,,0,5.000000e+000,1.000000e+000,4,4,2.657890e-002,0,,0,
1611888100.086,,1.000000e+002,2.276595e+001,3.787386e-004,1.930166e-008,5.466364e-002,5.136835e-005,3,9.805973e-001,1.825000e+000,,,,,,,,,,,,,,,,,,0,5.000000e+000,1.000000e+000,4,4,2.603912e-002,0,,0,
1611888367.377,,1.000000e+002,2.251553e+001,3.786986e-004,6.178198e-009,5.463113e-002,3.945037e-005,3,9.805615e-001,1.825000e+000,,,,,,,,,,,,,,,,,,0,5.000000e+000,1.000000e+000,4,4,2.415085e-002,0,,0,
1611888635.214,,1.000000e+002,2.226503e+001,3.786276e-004,2.470759e-008,5.455767e-002,3.097943e-005,3,9.805675e-001,1.825000e+000,,,,,,,,,,,,,,,,,,0,5.000000e+000,1.000000e+000,4,4,2.429962e-002,0,,0,
1611888904.439,,1.000000e+002,2.201330e+001,3.785403e-004,1.534650e-008,5.449024e-002,2.121448e-005,3,9.805498e-001,1.825000e+000,,,,,,,,,,,,,,,,,,0,5.000000e+000,1.000000e+000,4,4,2.314949e-002,0,,0,
1611889169.639,,1.000000e+002,2.176163e+001,3.784455e-004,1.753863e-008,5.445509e-002,1.219393e-005,3,9.805300e-001,1.825000e+000,,,,,,,,,,,,,,,,,,0,5.000000e+000,1.000000e+000,4,4,2.391052e-002,0,,0,
1611889434.419,,1.000000e+002,2.151172e+001,3.782833e-004,1.784881e-008,5.441400e-002,4.849993e-005,3,9.805253e-001,1.825000e+000,,,,,,,,,,,,,,,,,,0,5.000000e+000,1.000000e+000,4,4,2.032089e-002,0,,0,
1611889699.058,,1.000000e+002,2.126168e+001,3.780579e-004,2.064410e-008,5.437638e-002,3.034334e-005,3,9.805511e-001,1.825000e+000,,,,,,,,,,,,,,,,,,0,5.000000e+000,1.000000e+000,4,4,2.227974e-002,0,,0,
1611889963.899,,1.000000e+002,2.101025e+001,3.778376e-004,2.382971e-008,5.433567e-002,3.145748e-005,3,9.805397e-001,1.825000e+000,,,,,,,,,,,,,,,,,,0,5.000000e+000,1.000000e+000,4,4,2.060890e-002,0,,0,
1611890223.702,,1.000000e+002,2.075972e+001,3.775182e-004,1.696816e-008,5.424703e-002,2.104195e-005,3,9.805382e-001,1.825000e+000,,,,,,,,,,,,,,,,,,0,5.000000e+000,1.000000e+000,4,4,1.955986e-002,0,,0,
1611890485.143,,1.000000e+002,2.050872e+001,3.771156e-004,2.766260e-008,5.418930e-002,2.645257e-005,3,9.805683e-001,1.825000e+000,,,,,,,,,,,,,,,,,,0,5.000000e+000,1.000000e+000,4,4,1.797104e-002,0,,0,
1611890743.932,,1.000000e+002,2.025847e+001,3.766608e-004,2.145591e-008,5.418117e-002,2.538223e-005,3,9.805158e-001,1.825000e+000,,,,,,,,,,,,,,,,,,0,5.000000e+000,1.000000e+000,4,4,1.699066e-002,0,,0,
1611891000.069,,1.000000e+002,2.000797e+001,3.760986e-004,1.773448e-008,5.409154e-002,3.979029e-005,3,9.805014e-001,1.825000e+000,,,,,,,,,,,,,,,,,,0,5.000000e+000,1.000000e+000,4,4,1.712036e-002,0,,0,
1611891254.942,,1.000000e+002,1.975689e+001,3.754294e-004,3.135949e-008,5.404049e-002,1.976289e-005,3,9.805508e-001,1.825000e+000,,,,,,,,,,,,,,,,,,0,5.000000e+000,1.000000e+000,4,4,1.670074e-002,0,,0,
1611891507.413,,1.000000e+002,1.950656e+001,3.746501e-004,1.295227e-008,5.402780e-002,2.867114e-005,3,9.805171e-001,1.825000e+000,,,,,,,,,,,,,,,,,,0,5.000000e+000,1.000000e+000,4,4,1.527023e-002,0,,0,
1611891755.625,,1.000000e+002,1.925654e+001,3.737998e-004,3.167506e-008,5.396371e-002,2.134224e-005,3,9.804983e-001,1.825000e+000,,,,,,,,,,,,,,,,,,0,5.000000e+000,1.000000e+000,4,4,1.290131e-002,0,,0,
1611891999.609,,1.000000e+002,1.900638e+001,3.728295e-004,1.517273e-008,5.387168e-002,1.491713e-005,3,9.804816e-001,1.825000e+000,,,,,,,,,,,,,,,,,,0,5.000000e+000,1.000000e+000,4,4,1.403046e-002,0,,0,
1611892244.342,,1.000000e+002,1.875514e+001,3.718087e-004,7.048557e-009,5.389654e-002,1.414628e-005,3,9.805153e-001,1.825000e+000,,,,,,,,,,,,,,,,,,0,5.000000e+000,1.000000e+000,4,4,1.178169e-002,0,,0,
1611892486.689,,1.000000e+002,1.850478e+001,3.707194e-004,9.334832e-009,5.388049e-002,4.849738e-005,3,9.804798e-001,1.825000e+000,,,,,,,,,,,,,,,,,,0,5.000000e+000,1.000000e+000,4,4,1.101875e-002,0,,0,
1611892727.460,,1.000000e+002,1.825482e+001,3.696195e-004,2.440330e-008,5.377588e-002,3.038554e-005,3,9.804542e-001,1.825000e+000,,,,,,,,,,,,,,,,,,0,5.000000e+000,1.000000e+000,4,4,1.115990e-002,0,,0,
1611892967.263,,1.000000e+002,1.800401e+001,3.684845e-004,5.212268e-009,5.368836e-002,3.972626e-005,3,9.804906e-001,1.825000e+000,,,,,,,,,,,,,,,,,,0,5.000000e+000,1.000000e+000,4,4,1.000023e-002,0,,0,
1611893205.772,,1.000000e+002,1.775382e+001,3.673799e-004,1.587361e-008,5.365422e-002,2.993754e-005,3,9.804589e-001,1.825000e+000,,,,,,,,,,,,,,,,,,0,5.000000e+000,1.000000e+000,4,4,9.719849e-003,0,,0,
1611893442.815,,1.000000e+002,1.750384e+001,3.662622e-004,1.365547e-008,5.352637e-002,6.688531e-005,3,9.805042e-001,1.825000e+000,,,,,,,,,,,,,,,,,,0,5.000000e+000,1.000000e+000,4,4,8.628845e-003,0,,0,
1611893679.701,,1.000000e+002,1.725362e+001,3.651746e-004,8.547034e-009,5.343343e-002,3.394190e-005,3,9.804817e-001,1.825000e+000,,,,,,,,,,,,,,,,,,0,5.000000e+000,1.000000e+000,4,4,7.989883e-003,0,,0,
1611893913.826,,1.000000e+002,1.700291e+001,3.641165e-004,1.936990e-008,5.343874e-002,4.107027e-005,3,9.804797e-001,1.825000e+000,,,,,,,,,,,,,,,,,,0,5.000000e+000,1.000000e+000,4,4,6.990433e-003,0,,0,
1611894144.769,,1.000000e+002,1.675306e+001,3.631197e-004,1.676767e-008,5.331920e-002,3.128642e-005,3,9.804349e-001,1.825000e+000,,,,,,,,,,,,,,,,,,0,5.000000e+000,1.000000e+000,4,4,6.399155e-003,0,,0,
1611894376.773,,1.000000e+002,1.650246e+001,3.621624e-004,1.401333e-008,5.327182e-002,2.399017e-005,3,9.804139e-001,1.825000e+000,,,,,,,,,,,,,,,,,,0,5.000000e+000,1.000000e+000,4,4,4.749298e-003,0,,0,
1611894608.605,,1.000000e+002,1.625255e+001,3.612680e-004,2.292452e-008,5.321087e-002,4.529941e-005,3,9.804144e-001,1.825000e+000,,,,,,,,,,,,,,,,,,0,5.000000e+000,1.000000e+000,4,4,4.600525e-003,0,,0,
1611894837.301,,1.000000e+002,1.600305e+001,3.604067e-004,2.908262e-008,5.317849e-002,2.305448e-005,3,9.804620e-001,1.825000e+000,,,,,,,,,,,,,,,,,,0,5.000000e+000,1.000000e+000,4,4,5.500793e-003,0,,0,
1611895066.216,,1.000000e+002,1.575232e+001,3.595632e-004,8.628766e-009,5.315788e-002,2.670182e-005,3,9.803884e-001,1.825000e+000,,,,,,,,,,,,,,,,,,0,5.000000e+000,1.000000e+000,4,4,4.329681e-003,0,,0,
1611895294.023,,1.000000e+002,1.550197e+001,3.588102e-004,2.772185e-008,5.304987e-002,5.706066e-005,3,9.803950e-001,1.825000e+000,,,,,,,,,,,,,,,,,,0,5.000000e+000,1.000000e+000,4,4,4.190445e-003,0,,0,
1611895518.133,,1.000000e+002,1.525261e+001,3.581010e-004,1.422502e-008,5.298796e-002,1.963405e-005,3,9.803555e-001,1.825000e+000,,,,,,,,,,,,,,,,,,0,5.000000e+000,1.000000e+000,4,4,3.120422e-003,0,,0,
1611895740.621,,1.000000e+002,1.500215e+001,3.574483e-004,1.708079e-008,5.292718e-002,2.076619e-005,3,9.803277e-001,1.825000e+000,,,,,,,,,,,,,,,,,,0,5.000000e+000,1.000000e+000,4,4,3.020287e-003,0,,0,
1611895864.594,,1.000000e+002,1.450714e+001,3.562518e-004,1.594173e-008,5.271022e-002,4.133338e-005,3,9.802796e-001,1.825000e+000,,,,,,,,,,,,,,,,,,0,5.000000e+000,1.000000e+000,4,4,1.041985e-002,0,,0,
1611896038.519,,1.000000e+002,1.402271e+001,3.552615e-004,1.545120e-008,5.256438e-002,4.615579e-005,3,9.802158e-001,1.825000e+000,,,,,,,,,,,,,,,,,,0,5.000000e+000,1.000000e+000,4,4,6.110191e-003,0,,0,
1611896218.559,,1.000000e+002,1.351674e+001,3.544478e-004,1.496425e-008,5.239939e-002,4.341422e-005,3,9.801918e-001,1.825000e+000,,,,,,,,,,,,,,,,,,0,5.000000e+000,1.000000e+000,4,4,5.860329e-003,0,,0,
1611896394.870,,1.000000e+002,1.301062e+001,3.537700e-004,7.594371e-009,5.217251e-002,6.379463e-005,3,9.801117e-001,1.825000e+000,,,,,,,,,,,,,,,,,,0,5.000000e+000,1.000000e+000,4,4,5.290031e-003,0,,0,
1611896569.481,,1.000000e+002,1.250500e+001,3.532741e-004,6.940434e-009,5.198710e-002,4.628290e-005,3,9.800861e-001,1.825000e+000,,,,,,,,,,,,,,,,,,0,5.000000e+000,1.000000e+000,4,4,2.490044e-003,0,,0,
1611896743.983,,1.000000e+002,1.200225e+001,3.529717e-004,5.926210e-009,5.177106e-002,2.199309e-005,3,9.799781e-001,1.825000e+000,,,,,,,,,,,,,,,,,,0,5.000000e+000,1.000000e+000,4,4,1.129150e-003,0,,0,
1611896942.837,,1.000000e+002,1.152621e+001,3.528500e-004,1.607313e-008,5.156334e-002,2.636886e-005,3,9.798589e-001,1.825000e+000,,,,,,,,,,,,,,,,,,0,5.000000e+000,1.000000e+000,4,4,1.500130e-003,0,,0,
1611897140.957,,1.000000e+002,1.101787e+001,3.529140e-004,7.228187e-009,5.131584e-002,3.475140e-005,3,9.797692e-001,1.825000e+000,,,,,,,,,,,,,,,,,,0,5.000000e+000,1.000000e+000,4,4,1.749992e-003,0,,0,
1611897338.843,,1.000000e+002,1.050953e+001,3.531774e-004,8.230486e-009,5.102805e-002,1.235972e-005,3,9.796072e-001,1.825000e+000,,,,,,,,,,,,,,,,,,0,5.000000e+000,1.000000e+000,4,4,2.029419e-003,0,,0,
1611897534.000,,1.000000e+002,1.000198e+001,3.536623e-004,3.260062e-009,5.078430e-002,3.336093e-005,3,9.795280e-001,1.825000e+000,,,,,,,,,,,,,,,,,,0,5.000000e+000,1.000000e+000,4,4,2.269745e-003,0,,0,
1611897726.488,,1.000000e+002,9.501444e+000,3.543915e-004,2.578220e-008,5.046199e-002,4.962784e-005,3,9.793748e-001,1.825000e+000,,,,,,,,,,,,,,,,,,0,5.000000e+000,1.000000e+000,4,4,1.810074e-003,0,,0,
1611897916.684,,1.000000e+002,9.002310e+000,3.553517e-004,1.736739e-008,5.007672e-002,2.754805e-005,3,9.791744e-001,1.825000e+000,,,,,,,,,,,,,,,,,,0,5.000000e+000,1.000000e+000,4,4,4.481316e-003,0,,0,
1611898104.399,,1.000000e+002,8.501342e+000,3.566403e-004,2.333156e-008,4.967665e-002,5.160729e-005,3,9.789070e-001,1.825000e+000,,,,,,,,,,,,,,,,,,0,5.000000e+000,1.000000e+000,4,4,3.363609e-003,0,,0,
1611898290.788,,1.000000e+002,8.001770e+000,3.582026e-004,1.446343e-008,4.927389e-002,4.859615e-005,3,9.786231e-001,1.825000e+000,,,,,,,,,,,,,,,,,,0,5.000000e+000,1.000000e+000,4,4,6.312847e-003,0,,0,
1611898474.837,,1.000000e+002,7.502683e+000,3.601004e-004,1.487064e-008,4.885553e-002,1.045969e-005,3,9.783319e-001,1.825000e+000,,,,,,,,,,,,,,,,,,0,5.000000e+000,1.000000e+000,4,4,4.158020e-003,0,,0,
1611898658.091,,1.000000e+002,7.002271e+000,3.623285e-004,1.692860e-008,4.834807e-002,3.513525e-005,3,9.779757e-001,1.825000e+000,,,,,,,,,,,,,,,,,,0,5.000000e+000,1.000000e+000,4,4,5.105019e-003,0,,0,
1611898841.828,,1.000000e+002,6.502569e+000,3.650095e-004,2.738024e-008,4.775847e-002,3.743781e-005,3,9.775088e-001,1.825000e+000,,,,,,,,,,,,,,,,,,0,5.000000e+000,1.000000e+000,4,4,3.495216e-003,0,,0,
1611898954.991,,1.000000e+002,6.013710e+000,3.680755e-004,4.638778e-008,4.713831e-002,3.607141e-005,3,9.769338e-001,1.825000e+000,,,,,,,,,,,,,,,,,,0,5.000000e+000,1.000000e+000,4,4,8.164406e-003,0,,0,
1611899157.916,,1.000000e+002,5.752419e+000,3.699679e-004,1.257108e-008,4.678827e-002,1.618407e-005,3,9.765873e-001,1.825000e+000,,,,,,,,,,,,,,,,,,0,5.000000e+000,1.000000e+000,4,4,3.993988e-003,0,,0,
1611899355.225,,1.000000e+002,5.502898e+000,3.719025e-004,1.600996e-008,4.641820e-002,2.606929e-005,3,9.762543e-001,1.825000e+000,,,,,,,,,,,,,,,,,,0,5.000000e+000,1.000000e+000,4,4,3.547192e-003,0,,0,
1611899547.667,,1.000000e+002,5.254317e+000,3.739745e-004,1.127437e-008,4.600754e-002,3.279520e-005,3,9.758405e-001,1.825000e+000,,,,,,,,,,,,,,,,,,0,5.000000e+000,1.000000e+000,4,4,4.864216e-003,0,,0,
1611899737.348,,1.000000e+002,5.007309e+000,3.762076e-004,9.001854e-009,4.558718e-002,9.392045e-006,3,9.753920e-001,1.825000e+000,,,,,,,,,,,,,,,,,,0,5.000000e+000,1.000000e+000,4,4,6.865025e-003,0,,0,
1611899924.064,,1.000000e+002,4.752512e+000,3.786325e-004,2.790332e-008,4.511328e-002,1.452840e-005,3,9.748967e-001,1.825000e+000,,,,,,,,,,,,,,,,,,0,5.000000e+000,1.000000e+000,4,4,4.004002e-003,0,,0,
1611900101.998,,1.000000e+002,4.502157e+000,3.812406e-004,1.814775e-008,4.460335e-002,2.398805e-005,3,9.743892e-001,1.825000e+000,,,,,,,,,,,,,,,,,,0,5.000000e+000,1.000000e+000,4,4,3.618240e-003,0,,0,
1611900282.023,,1.000000e+002,4.249460e+000,3.842512e-004,3.166911e-008,4.404671e-002,2.865527e-005,3,9.736568e-001,1.825000e+000,,,,,,,,,,,,,,,,,,0,5.000000e+000,1.000000e+000,4,4,4.169941e-003,0,,0,
1611900430.535,,1.000000e+002,3.998865e+000,3.872672e-004,6.683270e-008,4.348342e-002,3.397013e-005,3,9.729943e-001,1.825000e+000,,,,,,,,,,,,,,,,,,0,5.000000e+000,1.000000e+000,4,4,1.237106e-002,0,,0,
1611900590.669,,1.000000e+002,3.751822e+000,3.906888e-004,4.838274e-008,4.279995e-002,2.164283e-005,3,9.722105e-001,1.825000e+000,,,,,,,,,,,,,,,,,,0,5.000000e+000,1.000000e+000,4,4,1.085591e-002,0,,0,
1611900738.386,,1.000000e+002,3.500555e+000,3.945184e-004,1.137816e-008,4.204813e-002,2.638467e-005,3,9.712788e-001,1.825000e+000,,,,,,,,,,,,,,,,,,0,5.000000e+000,1.000000e+000,4,4,6.853104e-003,0,,0,
1611900885.790,,1.000000e+002,3.249748e+000,3.986044e-004,4.323183e-008,4.118067e-002,2.924851e-005,3,9.701492e-001,1.825000e+000,,,,,,,,,,,,,,,,,,0,5.000000e+000,1.000000e+000,4,4,7.910967e-003,0,,0,
1611901062.944,,1.000000e+002,3.002917e+000,4.030949e-004,2.651266e-008,4.017084e-002,5.907583e-006,3,9.688653e-001,1.825000e+000,,,,,,,,,,,,,,,,,,0,5.000000e+000,1.000000e+000,4,4,6.757975e-003,0,,0,
1611901253.311,,1.000000e+002,2.753125e+000,4.081374e-004,4.359714e-008,3.909345e-002,4.145516e-005,3,9.673655e-001,1.825000e+000,,,,,,,,,,,,,,,,,,0,5.000000e+000,1.000000e+000,4,4,6.607056e-003,0,,0,
1611901452.742,,1.000000e+002,2.503385e+000,4.137686e-004,3.125207e-008,3.777364e-002,3.655175e-005,3,9.655313e-001,1.825000e+000,,,,,,,,,,,,,,,,,,0,5.000000e+000,1.000000e+000,4,4,6.802797e-003,0,,0,
1611901668.647,,1.000000e+002,2.252802e+000,4.203507e-004,4.369400e-008,3.621525e-002,2.842870e-005,3,9.632718e-001,1.825000e+000,,,,,,,,,,,,,,,,,,0,5.000000e+000,1.000000e+000,4,4,6.604910e-003,0,,0,
1611901960.414,,1.000000e+002,2.000793e+000,4.284551e-004,6.177672e-008,3.420712e-002,2.662942e-005,3,9.603032e-001,1.825000e+000,,,,,,,,,,,,,,,,,,0,5.000000e+000,1.000000e+000,4,4,5.977988e-003,0,,0,