File: Analysis_of_CrCl2pym/MPMS/MPMS_CrCl2pym_MH.rso.dat
[Header]
TITLE,MPMS RSO Measurement
BYAPP,MPMS Measurement,1.1,Summary
FILEOPENTIME, 1622262650.763000 5/29/2021, 5:30:50 AM

INFO, APPNAME, MPMS MultiVu Application, Revision 1.61,  Build 082

INFO, NAME, CrCl2pym
INFO, WEIGHT, 26.600
INFO, AREA, 1.000
INFO, LENGTH, 1.000
INFO, SHAPE, -
INFO, COMMENT, 44.5mg eicosane
INFO, SEQUENCE FILE: JP_ZFC_FC_MH_210528_sicogi_CrCl2pym.seq


INFO, BACKGROUND DATA FILE:, None


STARTUPAXIS,X,4,LINEAR,AUTO,0.000000,0.000000
STARTUPAXIS,Y1,5,LINEAR,AUTO,0.000000,0.000000


STARTUPGROUP,Longitudinal
FIELDGROUP,Longitudinal,1,2,3,4,5,6,7,8,9,10,11,19,20,21,22,23,35
FIELDGROUP,Transverse,1,2,3,4,12,13,14,15,16,17,18,24,25,26,27,28,35

PLOT_APPEARANCE,ALL,HORZ_GRID_ON,VERT_GRID_ON,MARKERS_AND_LINES

[Data]
Time,Comment,Field (Oe),Temperature (K),Long Moment (emu),Long Scan Std Dev,Long Offset (cm),Long Offset Std Dev,Long Algorithm,Long Reg Fit,Long Reg Factor,Trans Moment (emu),Trans Scan Std Dev,Trans Offset (cm),Trans Offset Std Dev,Trans Algorithm,Trans Reg Fit,Trans Reg Factor,Long Moment [w/o ABS] (emu),Long Scan Std Dev [w/o ABS],Long Offset [w/o ABS] (cm),Long Offset Std Dev [w/o ABS],Long Reg Fit [w/o ABS],Trans Moment [w/o ABS] (emu),Trans Scan Std Dev [w/o ABS],Trans Offset [w/o ABS] (cm),Trans Offset Std Dev [w/o ABS],Trans Reg Fit [w/o ABS],RSO Position (deg),Amplitude (cm),Frequency,Cycles to Average,Scans per Measurement,Delta Temp (K),Error,EC Comp. Running,Using ABS,
1622262650.763,,0.000000e+000,1.999979e+000,6.421298e-007,8.719711e-008,0.000000e+000,0.000000e+000,2,8.694528e-001,1.825000e+000,,,,,,,,,,,,,,,,,,0,3.000000e+000,1.000000e+000,4,4,1.839876e-003,0,,0,
1622262705.004,,1.006293e+002,2.001592e+000,4.492344e-004,8.626286e-008,0.000000e+000,0.000000e+000,2,9.689800e-001,1.825000e+000,,,,,,,,,,,,,,,,,,0,3.000000e+000,1.000000e+000,4,4,6.520748e-004,0,,0,
1622262746.718,,2.031972e+002,2.001383e+000,9.067183e-004,2.046288e-007,0.000000e+000,0.000000e+000,2,9.688941e-001,1.825000e+000,,,,,,,,,,,,,,,,,,0,3.000000e+000,1.000000e+000,4,4,5.271435e-004,0,,0,
1622262788.027,,3.109066e+002,2.000351e+000,1.389716e-003,2.182205e-006,0.000000e+000,0.000000e+000,2,9.688275e-001,1.825000e+000,,,,,,,,,,,,,,,,,,0,3.000000e+000,1.000000e+000,4,4,7.200241e-004,0,,0,
1622262829.867,,4.174255e+002,1.999226e+000,1.881747e-003,1.027895e-005,0.000000e+000,0.000000e+000,2,9.687743e-001,1.825000e+000,,,,,,,,,,,,,,,,,,0,3.000000e+000,1.000000e+000,4,4,6.629229e-004,0,,0,
1622262879.584,,5.176543e+002,1.998341e+000,2.316840e-003,5.748083e-006,0.000000e+000,0.000000e+000,2,9.687749e-001,1.825000e+000,,,,,,,,,,,,,,,,,,0,3.000000e+000,1.000000e+000,4,4,3.030300e-004,0,,0,
1622262920.362,,6.213285e+002,1.998125e+000,2.755284e-003,1.011214e-005,0.000000e+000,0.000000e+000,2,9.689674e-001,1.825000e+000,,,,,,,,,,,,,,,,,,0,3.000000e+000,1.000000e+000,4,4,1.790524e-004,0,,0,
1622262977.802,,7.161947e+002,1.998793e+000,3.185820e-003,1.231933e-005,0.000000e+000,0.000000e+000,2,9.691159e-001,1.825000e+000,,,,,,,,,,,,,,,,,,0,3.000000e+000,1.000000e+000,4,4,1.116991e-003,0,,0,
1622263030.545,,8.371475e+002,1.999948e+000,3.617367e-003,2.585445e-007,0.000000e+000,0.000000e+000,2,9.689239e-001,1.825000e+000,,,,,,,,,,,,,,,,,,0,3.000000e+000,1.000000e+000,4,4,5.120039e-004,0,,0,
1622263072.603,,9.111314e+002,2.000358e+000,4.062450e-003,1.435282e-006,0.000000e+000,0.000000e+000,2,9.689924e-001,1.825000e+000,,,,,,,,,,,,,,,,,,0,3.000000e+000,1.000000e+000,4,4,3.049374e-004,0,,0,
1622263549.808,,2.045246e+003,2.000923e+000,9.091430e-003,7.114004e-006,0.000000e+000,0.000000e+000,2,9.693362e-001,1.825000e+000,,,,,,,,,,,,,,,,,,0,3.000000e+000,1.000000e+000,4,3,3.330708e-004,1,,0,
1622263722.672,,3.037632e+003,2.000055e+000,1.344704e-002,1.609159e-006,0.000000e+000,0.000000e+000,2,9.698730e-001,1.825000e+000,,,,,,,,,,,,,,,,,,0,3.000000e+000,1.000000e+000,4,4,6.006956e-003,0,,0,
1622263767.974,,4.032229e+003,2.007891e+000,1.777456e-002,1.232979e-006,0.000000e+000,0.000000e+000,2,9.706520e-001,1.825000e+000,,,,,,,,,,,,,,,,,,0,3.000000e+000,1.000000e+000,4,4,1.577139e-003,0,,0,
1622263812.263,,5.031146e+003,2.007092e+000,2.208833e-002,3.153413e-006,0.000000e+000,0.000000e+000,2,9.713997e-001,1.825000e+000,,,,,,,,,,,,,,,,,,0,3.000000e+000,1.000000e+000,4,4,1.533031e-003,0,,0,
1622263856.770,,6.030485e+003,2.005166e+000,2.635890e-002,1.035017e-006,0.000000e+000,0.000000e+000,2,9.722460e-001,1.825000e+000,,,,,,,,,,,,,,,,,,0,3.000000e+000,1.000000e+000,4,4,8.680820e-004,0,,0,
1622263901.245,,7.032349e+003,2.003227e+000,3.058942e-002,2.513949e-006,0.000000e+000,0.000000e+000,2,9.730693e-001,1.825000e+000,,,,,,,,,,,,,,,,,,0,3.000000e+000,1.000000e+000,4,4,1.227140e-003,0,,0,
1622263946.532,,8.031800e+003,2.001661e+000,3.476048e-002,9.112835e-007,0.000000e+000,0.000000e+000,2,9.739154e-001,1.825000e+000,,,,,,,,,,,,,,,,,,0,3.000000e+000,1.000000e+000,4,4,3.049374e-004,0,,0,
1622263991.335,,9.033978e+003,2.000881e+000,3.889498e-002,2.279116e-006,0.000000e+000,0.000000e+000,2,9.747365e-001,1.825000e+000,,,,,,,,,,,,,,,,,,0,3.000000e+000,1.000000e+000,4,4,4.720688e-004,0,,0,
1622264044.531,,1.003469e+004,2.000460e+000,4.297694e-002,6.051466e-007,0.000000e+000,0.000000e+000,2,9.755210e-001,1.825000e+000,,,,,,,,,,,,,,,,,,0,3.000000e+000,1.000000e+000,4,4,2.069473e-004,0,,0,
1622264143.716,,1.504487e+004,1.999811e+000,6.285785e-002,2.152616e-006,0.000000e+000,0.000000e+000,2,9.783248e-001,1.825000e+000,,,,,,,,,,,,,,,,,,0,3.000000e+000,1.000000e+000,4,4,4.420280e-004,0,,0,
1622264211.514,,2.006053e+004,1.999490e+000,8.201129e-002,5.212306e-006,0.000000e+000,0.000000e+000,2,9.791189e-001,1.825000e+000,,,,,,,,,,,,,,,,,,0,3.000000e+000,1.000000e+000,4,4,6.079674e-004,0,,0,
1622264271.169,,2.507935e+004,1.999332e+000,1.006869e-001,6.916354e-006,0.000000e+000,0.000000e+000,2,9.785842e-001,1.825000e+000,,,,,,,,,,,,,,,,,,0,3.000000e+000,1.000000e+000,4,4,2.350807e-004,0,,0,
1622264330.246,,3.009605e+004,1.999492e+000,1.190313e-001,6.578416e-006,0.000000e+000,0.000000e+000,2,9.775557e-001,1.825000e+000,,,,,,,,,,,,,,,,,,0,3.000000e+000,1.000000e+000,4,4,7.599592e-004,0,,0,
1622264390.119,,3.511330e+004,1.999338e+000,1.371124e-001,1.016634e-005,0.000000e+000,0.000000e+000,2,9.762470e-001,1.825000e+000,,,,,,,,,,,,,,,,,,0,3.000000e+000,1.000000e+000,4,4,8.289814e-004,0,,0,
1622264449.446,,4.012843e+004,1.999559e+000,1.550308e-001,3.306895e-005,0.000000e+000,0.000000e+000,2,9.750031e-001,1.825000e+000,,,,,,,,,,,,,,,,,,0,3.000000e+000,1.000000e+000,4,4,6.769896e-004,0,,0,
1622264507.727,,4.514989e+004,1.999448e+000,1.727701e-001,1.449175e-005,0.000000e+000,0.000000e+000,2,9.737443e-001,1.825000e+000,,,,,,,,,,,,,,,,,,0,3.000000e+000,1.000000e+000,4,4,6.080866e-004,0,,0,
1622264567.335,,5.016502e+004,1.999517e+000,1.904411e-001,7.695073e-005,0.000000e+000,0.000000e+000,2,9.728742e-001,1.825000e+000,,,,,,,,,,,,,,,,,,0,3.000000e+000,1.000000e+000,4,4,7.189512e-004,0,,0,
1622264647.941,,5.013025e+004,1.999307e+000,1.905021e-001,1.369203e-005,0.000000e+000,0.000000e+000,2,9.729105e-001,1.825000e+000,,,,,,,,,,,,,,,,,,0,3.000000e+000,1.000000e+000,4,4,5.800724e-004,0,,0,
1622264708.609,,4.511617e+004,1.999066e+000,1.727990e-001,7.291374e-006,0.000000e+000,0.000000e+000,2,9.741302e-001,1.825000e+000,,,,,,,,,,,,,,,,,,0,3.000000e+000,1.000000e+000,4,4,9.109974e-004,0,,0,
1622264769.278,,4.009682e+004,1.998761e+000,1.550543e-001,5.384951e-006,0.000000e+000,0.000000e+000,2,9.754437e-001,1.825000e+000,,,,,,,,,,,,,,,,,,0,3.000000e+000,1.000000e+000,4,4,7.729530e-004,0,,0,
1622264830.211,,3.507959e+004,1.998734e+000,1.371835e-001,4.621442e-006,0.000000e+000,0.000000e+000,2,9.767169e-001,1.825000e+000,,,,,,,,,,,,,,,,,,0,3.000000e+000,1.000000e+000,4,4,3.859997e-004,0,,0,
1622264889.772,,3.006813e+004,1.998722e+000,1.191524e-001,8.381928e-006,0.000000e+000,0.000000e+000,2,9.779764e-001,1.825000e+000,,,,,,,,,,,,,,,,,,0,3.000000e+000,1.000000e+000,4,4,1.021028e-003,0,,0,
1622264949.380,,2.505248e+004,1.998775e+000,1.008511e-001,8.998267e-006,0.000000e+000,0.000000e+000,2,9.790037e-001,1.825000e+000,,,,,,,,,,,,,,,,,,0,3.000000e+000,1.000000e+000,4,4,4.969835e-004,0,,0,
1622265009.456,,2.003419e+004,1.998551e+000,8.217321e-002,5.043174e-006,0.000000e+000,0.000000e+000,2,9.794376e-001,1.825000e+000,,,,,,,,,,,,,,,,,,0,3.000000e+000,1.000000e+000,4,4,1.446962e-003,0,,0,
1622265068.658,,1.502011e+004,1.990880e+000,6.303182e-002,9.963856e-006,0.000000e+000,0.000000e+000,2,9.785362e-001,1.825000e+000,,,,,,,,,,,,,,,,,,0,3.000000e+000,1.000000e+000,4,4,1.178980e-003,0,,0,
1622265167.546,,1.002858e+004,1.996672e+000,4.312321e-002,8.818261e-006,0.000000e+000,0.000000e+000,2,9.756198e-001,1.825000e+000,,,,,,,,,,,,,,,,,,0,3.000000e+000,1.000000e+000,4,4,3.677964e-003,0,,0,
1622265211.726,,9.027238e+003,2.000748e+000,3.902194e-002,6.081546e-006,0.000000e+000,0.000000e+000,2,9.748130e-001,1.825000e+000,,,,,,,,,,,,,,,,,,0,3.000000e+000,1.000000e+000,4,4,3.033876e-003,0,,0,
1622265255.640,,8.023791e+003,2.003063e+000,3.487459e-002,1.127613e-006,0.000000e+000,0.000000e+000,2,9.740160e-001,1.825000e+000,,,,,,,,,,,,,,,,,,0,3.000000e+000,1.000000e+000,4,4,1.142025e-003,0,,0,
1622265300.349,,7.021398e+003,2.003136e+000,3.068711e-002,5.180915e-006,0.000000e+000,0.000000e+000,2,9.731727e-001,1.825000e+000,,,,,,,,,,,,,,,,,,0,3.000000e+000,1.000000e+000,4,4,4.458427e-004,0,,0,
1622265345.277,,6.016367e+003,2.001698e+000,2.644194e-002,4.271553e-006,0.000000e+000,0.000000e+000,2,9.722768e-001,1.825000e+000,,,,,,,,,,,,,,,,,,0,3.000000e+000,1.000000e+000,4,4,9.582043e-004,0,,0,
1622265397.335,,5.015027e+003,1.999790e+000,2.215976e-002,5.771325e-007,0.000000e+000,0.000000e+000,2,9.714341e-001,1.825000e+000,,,,,,,,,,,,,,,,,,0,3.000000e+000,1.000000e+000,4,4,7.189512e-004,0,,0,
1622265442.091,,4.012000e+003,1.998698e+000,1.782730e-002,1.328459e-006,0.000000e+000,0.000000e+000,2,9.706872e-001,1.825000e+000,,,,,,,,,,,,,,,,,,0,3.000000e+000,1.000000e+000,4,4,1.240969e-004,0,,0,
1622265486.614,,3.009922e+003,1.998710e+000,1.345366e-002,1.477777e-006,0.000000e+000,0.000000e+000,2,9.701825e-001,1.825000e+000,,,,,,,,,,,,,,,,,,0,3.000000e+000,1.000000e+000,4,4,5.789995e-004,0,,0,
1622265539.825,,2.005526e+003,1.999500e+000,9.031234e-003,1.681182e-006,0.000000e+000,0.000000e+000,2,9.699469e-001,1.825000e+000,,,,,,,,,,,,,,,,,,0,3.000000e+000,1.000000e+000,4,4,6.909370e-004,0,,0,
1622265623.785,,1.003511e+003,2.000271e+000,4.565203e-003,2.215714e-006,0.000000e+000,0.000000e+000,2,9.703180e-001,1.825000e+000,,,,,,,,,,,,,,,,,,0,3.000000e+000,1.000000e+000,4,4,9.410381e-004,0,,0,
1622265664.501,,9.032085e+002,2.000666e+000,4.115713e-003,9.132865e-007,0.000000e+000,0.000000e+000,2,9.706733e-001,1.825000e+000,,,,,,,,,,,,,,,,,,0,3.000000e+000,1.000000e+000,4,4,3.049374e-004,0,,0,
1622265706.200,,8.028636e+002,2.000558e+000,3.668352e-003,1.816286e-006,0.000000e+000,0.000000e+000,2,9.705783e-001,1.825000e+000,,,,,,,,,,,,,,,,,,0,3.000000e+000,1.000000e+000,4,4,1.389980e-004,0,,0,
1622265746.728,,7.025609e+002,2.000334e+000,3.220398e-003,1.829253e-006,0.000000e+000,0.000000e+000,2,9.707533e-001,1.825000e+000,,,,,,,,,,,,,,,,,,0,3.000000e+000,1.000000e+000,4,4,9.703636e-005,0,,0,
1622265788.271,,6.020897e+002,2.000093e+000,2.772418e-003,1.113729e-006,0.000000e+000,0.000000e+000,2,9.709545e-001,1.825000e+000,,,,,,,,,,,,,,,,,,0,3.000000e+000,1.000000e+000,4,4,8.296967e-005,0,,0,
1622265837.583,,5.019873e+002,1.999908e+000,2.325771e-003,1.512512e-006,0.000000e+000,0.000000e+000,2,9.712459e-001,1.825000e+000,,,,,,,,,,,,,,,,,,0,3.000000e+000,1.000000e+000,4,4,1.380444e-004,0,,0,
1622265878.112,,4.016846e+002,1.999822e+000,1.878331e-003,1.320161e-006,0.000000e+000,0.000000e+000,2,9.717351e-001,1.825000e+000,,,,,,,,,,,,,,,,,,0,3.000000e+000,1.000000e+000,4,4,2.350807e-004,0,,0,
1622265919.686,,3.014557e+002,1.999868e+000,1.431437e-003,7.793442e-007,0.000000e+000,0.000000e+000,2,9.726110e-001,1.825000e+000,,,,,,,,,,,,,,,,,,0,3.000000e+000,1.000000e+000,4,4,3.180504e-004,0,,0,
1622265960.761,,2.010056e+002,1.999891e+000,9.834631e-004,8.894131e-007,0.000000e+000,0.000000e+000,2,9.738070e-001,1.825000e+000,,,,,,,,,,,,,,,,,,0,3.000000e+000,1.000000e+000,4,4,3.041029e-004,0,,0,
1622266009.995,,1.008189e+002,2.000105e+000,5.363127e-004,4.661953e-007,0.000000e+000,0.000000e+000,2,9.766374e-001,1.825000e+000,,,,,,,,,,,,,,,,,,0,3.000000e+000,1.000000e+000,4,4,1.659393e-004,0,,0,
1622266060.554,,3.055438e-001,2.000122e+000,8.112554e-005,3.195940e-007,0.000000e+000,0.000000e+000,2,9.399146e-001,1.825000e+000,,,,,,,,,,,,,,,,,,0,3.000000e+000,1.000000e+000,4,4,2.899170e-004,0,,0,
1622266141.659,,3.055438e-001,2.000010e+000,7.956474e-005,1.872529e-007,0.000000e+000,0.000000e+000,2,9.400993e-001,1.825000e+000,,,,,,,,,,,,,,,,,,0,3.000000e+000,1.000000e+000,4,4,7.328987e-004,0,,0,
1622266202.015,,-1.008821e+002,2.000481e+000,-3.719626e-004,2.470177e-007,0.000000e+000,0.000000e+000,2,9.550216e-001,1.825000e+000,,,,,,,,,,,,,,,,,,0,3.000000e+000,1.000000e+000,4,4,2.758503e-004,0,,0,
1622266250.984,,-2.010689e+002,2.000424e+000,-8.180368e-004,1.880555e-007,0.000000e+000,0.000000e+000,2,9.628900e-001,1.825000e+000,,,,,,,,,,,,,,,,,,0,3.000000e+000,1.000000e+000,4,4,4.196167e-005,0,,0,
1622266291.762,,-3.015084e+002,2.000169e+000,-1.264895e-003,1.389584e-006,0.000000e+000,0.000000e+000,2,9.646977e-001,1.825000e+000,,,,,,,,,,,,,,,,,,0,3.000000e+000,1.000000e+000,4,4,4.196167e-005,0,,0,
1622266333.555,,-4.017373e+002,1.999896e+000,-1.709934e-003,1.527641e-006,0.000000e+000,0.000000e+000,2,9.663616e-001,1.825000e+000,,,,,,,,,,,,,,,,,,0,3.000000e+000,1.000000e+000,4,4,9.596348e-005,0,,0,
1622266383.366,,-5.019978e+002,1.999830e+000,-2.157727e-003,3.525712e-007,0.000000e+000,0.000000e+000,2,9.666578e-001,1.825000e+000,,,,,,,,,,,,,,,,,,0,3.000000e+000,1.000000e+000,4,4,2.900362e-004,0,,0,
1622266425.205,,-6.021740e+002,1.999842e+000,-2.602434e-003,7.869272e-007,0.000000e+000,0.000000e+000,2,9.667826e-001,1.825000e+000,,,,,,,,,,,,,,,,,,0,3.000000e+000,1.000000e+000,4,4,1.519918e-004,0,,0,
1622266465.937,,-7.026873e+002,1.999948e+000,-3.048389e-003,8.253944e-007,0.000000e+000,0.000000e+000,2,9.674935e-001,1.825000e+000,,,,,,,,,,,,,,,,,,0,3.000000e+000,1.000000e+000,4,4,2.628565e-004,0,,0,
1622266507.011,,-8.029058e+002,1.999953e+000,-3.494712e-003,5.871447e-007,0.000000e+000,0.000000e+000,2,9.675946e-001,1.825000e+000,,,,,,,,,,,,,,,,,,0,3.000000e+000,1.000000e+000,4,4,1.940727e-004,0,,0,
1622266548.585,,-9.032713e+002,2.000029e+000,-3.939724e-003,1.078022e-006,0.000000e+000,0.000000e+000,2,9.678804e-001,1.825000e+000,,,,,,,,,,,,,,,,,,0,3.000000e+000,1.000000e+000,4,4,3.041029e-004,0,,0,
1622266598.896,,-1.003469e+003,2.000084e+000,-4.383674e-003,1.398963e-006,0.000000e+000,0.000000e+000,2,9.679838e-001,1.825000e+000,,,,,,,,,,,,,,,,,,0,3.000000e+000,1.000000e+000,4,4,2.899170e-004,0,,0,
1622266691.045,,-2.010267e+003,1.999999e+000,-8.837382e-003,3.650476e-007,0.000000e+000,0.000000e+000,2,9.688076e-001,1.825000e+000,,,,,,,,,,,,,,,,,,0,3.000000e+000,1.000000e+000,4,4,3.730059e-004,0,,0,
1622266735.349,,-3.015295e+003,2.000214e+000,-1.324815e-002,7.187620e-007,0.000000e+000,0.000000e+000,2,9.694951e-001,1.825000e+000,,,,,,,,,,,,,,,,,,0,3.000000e+000,1.000000e+000,4,4,2.908707e-004,0,,0,
1622266779.575,,-4.017268e+003,2.000254e+000,-1.761603e-002,6.729814e-007,0.000000e+000,0.000000e+000,2,9.702734e-001,1.825000e+000,,,,,,,,,,,,,,,,,,0,3.000000e+000,1.000000e+000,4,4,2.770424e-004,0,,0,
1622266832.740,,-5.020294e+003,2.000169e+000,-2.194766e-002,1.396384e-006,0.000000e+000,0.000000e+000,2,9.710434e-001,1.825000e+000,,,,,,,,,,,,,,,,,,0,3.000000e+000,1.000000e+000,4,4,1.239777e-004,0,,0,
1622266877.715,,-6.021951e+003,1.999955e+000,-2.622560e-002,1.453383e-006,0.000000e+000,0.000000e+000,2,9.719621e-001,1.825000e+000,,,,,,,,,,,,,,,,,,0,3.000000e+000,1.000000e+000,4,4,1.379251e-004,0,,0,
1622266922.955,,-7.027084e+003,1.999854e+000,-3.046528e-002,1.431249e-006,0.000000e+000,0.000000e+000,2,9.728669e-001,1.825000e+000,,,,,,,,,,,,,,,,,,0,3.000000e+000,1.000000e+000,4,4,3.460646e-004,0,,0,
1622266966.931,,-8.029056e+003,1.999879e+000,-3.465115e-002,1.934043e-006,0.000000e+000,0.000000e+000,2,9.737858e-001,1.825000e+000,,,,,,,,,,,,,,,,,,0,3.000000e+000,1.000000e+000,4,4,4.009008e-004,0,,0,
1622267011.376,,-9.032718e+003,2.000026e+000,-3.878963e-002,2.472735e-006,0.000000e+000,0.000000e+000,2,9.746629e-001,1.825000e+000,,,,,,,,,,,,,,,,,,0,3.000000e+000,1.000000e+000,4,4,3.039837e-004,0,,0,
1622267063.792,,-1.003532e+004,2.000128e+000,-4.288177e-002,1.584989e-006,0.000000e+000,0.000000e+000,2,9.754614e-001,1.825000e+000,,,,,,,,,,,,,,,,,,0,3.000000e+000,1.000000e+000,4,4,1.251698e-004,0,,0,
1622267161.869,,-1.504592e+004,1.999873e+000,-6.276730e-002,2.783295e-006,0.000000e+000,0.000000e+000,2,9.784389e-001,1.825000e+000,,,,,,,,,,,,,,,,,,0,3.000000e+000,1.000000e+000,4,4,8.020401e-004,0,,0,
1622267229.402,,-2.006158e+004,2.000334e+000,-8.192395e-002,7.566313e-006,0.000000e+000,0.000000e+000,2,9.792928e-001,1.825000e+000,,,,,,,,,,,,,,,,,,0,3.000000e+000,1.000000e+000,4,4,3.600121e-004,0,,0,
1622267288.744,,-2.507988e+004,2.000282e+000,-1.006314e-001,9.216077e-006,0.000000e+000,0.000000e+000,2,9.788417e-001,1.825000e+000,,,,,,,,,,,,,,,,,,0,3.000000e+000,1.000000e+000,4,4,4.150867e-004,0,,0,
1622267348.352,,-3.009659e+004,2.000053e+000,-1.189630e-001,6.654227e-006,0.000000e+000,0.000000e+000,2,9.777517e-001,1.825000e+000,,,,,,,,,,,,,,,,,,0,3.000000e+000,1.000000e+000,4,4,3.598928e-004,0,,0,
1622267407.429,,-3.511541e+004,1.999974e+000,-1.370406e-001,1.059952e-005,0.000000e+000,0.000000e+000,2,9.764593e-001,1.825000e+000,,,,,,,,,,,,,,,,,,0,3.000000e+000,1.000000e+000,4,4,4.699230e-004,0,,0,
1622267466.772,,-4.012948e+004,2.000024e+000,-1.549463e-001,1.133359e-005,0.000000e+000,0.000000e+000,2,9.751909e-001,1.825000e+000,,,,,,,,,,,,,,,,,,0,3.000000e+000,1.000000e+000,4,4,6.220341e-004,0,,0,
1622267526.177,,-4.514883e+004,2.000136e+000,-1.727225e-001,7.750404e-006,0.000000e+000,0.000000e+000,2,9.739594e-001,1.825000e+000,,,,,,,,,,,,,,,,,,0,3.000000e+000,1.000000e+000,4,4,5.539656e-004,0,,0,
1622267586.003,,-5.016818e+004,2.000193e+000,-1.904415e-001,9.792519e-006,0.000000e+000,0.000000e+000,2,9.728149e-001,1.825000e+000,,,,,,,,,,,,,,,,,,0,3.000000e+000,1.000000e+000,4,4,5.680323e-004,0,,0,
1622267666.827,,-5.013130e+004,2.000121e+000,-1.904515e-001,1.078180e-005,0.000000e+000,0.000000e+000,2,9.730540e-001,1.825000e+000,,,,,,,,,,,,,,,,,,0,3.000000e+000,1.000000e+000,4,4,6.231070e-004,0,,0,
1622267727.542,,-4.511617e+004,2.000073e+000,-1.727545e-001,1.110440e-005,0.000000e+000,0.000000e+000,2,9.742837e-001,1.825000e+000,,,,,,,,,,,,,,,,,,0,3.000000e+000,1.000000e+000,4,4,3.460646e-004,0,,0,
1622267788.429,,-4.009682e+004,1.999920e+000,-1.550146e-001,1.397397e-005,0.000000e+000,0.000000e+000,2,9.755780e-001,1.825000e+000,,,,,,,,,,,,,,,,,,0,3.000000e+000,1.000000e+000,4,4,4.560947e-004,0,,0,
1622267848.832,,-3.507959e+004,1.999897e+000,-1.371467e-001,9.336859e-006,0.000000e+000,0.000000e+000,2,9.768729e-001,1.825000e+000,,,,,,,,,,,,,,,,,,0,3.000000e+000,1.000000e+000,4,4,5.260706e-004,0,,0,
1622267907.660,,-3.006971e+004,2.000038e+000,-1.190995e-001,4.500369e-006,0.000000e+000,0.000000e+000,2,9.780841e-001,1.825000e+000,,,,,,,,,,,,,,,,,,0,3.000000e+000,1.000000e+000,4,4,5.670786e-004,0,,0,
1622267968.375,,-2.505459e+004,2.000045e+000,-1.007885e-001,7.558168e-006,0.000000e+000,0.000000e+000,2,9.790721e-001,1.825000e+000,,,,,,,,,,,,,,,,,,0,3.000000e+000,1.000000e+000,4,4,5.949736e-004,0,,0,
1622268027.515,,-2.003577e+004,2.000085e+000,-8.212173e-002,9.087895e-006,0.000000e+000,0.000000e+000,2,9.794893e-001,1.825000e+000,,,,,,,,,,,,,,,,,,0,3.000000e+000,1.000000e+000,4,4,5.810261e-004,0,,0,
1622268087.606,,-1.502169e+004,2.000064e+000,-6.297465e-002,6.148078e-006,0.000000e+000,0.000000e+000,2,9.785656e-001,1.825000e+000,,,,,,,,,,,,,,,,,,0,3.000000e+000,1.000000e+000,4,4,5.120039e-004,0,,0,
1622268186.417,,-1.002858e+004,1.999889e+000,-4.309471e-002,1.974500e-006,0.000000e+000,0.000000e+000,2,9.755749e-001,1.825000e+000,,,,,,,,,,,,,,,,,,0,3.000000e+000,1.000000e+000,4,4,7.610321e-004,0,,0,
1622268230.378,,-9.027871e+003,2.000327e+000,-3.899851e-002,3.473655e-006,0.000000e+000,0.000000e+000,2,9.748031e-001,1.825000e+000,,,,,,,,,,,,,,,,,,0,3.000000e+000,1.000000e+000,4,4,5.810261e-004,0,,0,
1622268274.869,,-8.024843e+003,2.000417e+000,-3.485616e-002,4.545915e-006,0.000000e+000,0.000000e+000,2,9.739347e-001,1.825000e+000,,,,,,,,,,,,,,,,,,0,3.000000e+000,1.000000e+000,4,4,2.770424e-004,0,,0,
1622268319.095,,-7.022452e+003,2.000263e+000,-3.067027e-002,2.275713e-006,0.000000e+000,0.000000e+000,2,9.730694e-001,1.825000e+000,,,,,,,,,,,,,,,,,,0,3.000000e+000,1.000000e+000,4,4,3.190041e-004,0,,0,
1622268364.070,,-6.017631e+003,2.000060e+000,-2.642528e-002,3.611480e-006,0.000000e+000,0.000000e+000,2,9.721622e-001,1.825000e+000,,,,,,,,,,,,,,,,,,0,3.000000e+000,1.000000e+000,4,4,2.080202e-004,0,,0,
1622268416.439,,-5.015659e+003,1.999963e+000,-2.214096e-002,2.965567e-006,0.000000e+000,0.000000e+000,2,9.713970e-001,1.825000e+000,,,,,,,,,,,,,,,,,,0,3.000000e+000,1.000000e+000,4,4,1.940727e-004,0,,0,
1622268460.696,,-4.012211e+003,1.999839e+000,-1.780707e-002,2.808475e-006,0.000000e+000,0.000000e+000,2,9.706900e-001,1.825000e+000,,,,,,,,,,,,,,,,,,0,3.000000e+000,1.000000e+000,4,4,2.210140e-004,0,,0,
1622268505.188,,-3.010133e+003,1.999970e+000,-1.343334e-002,2.864768e-006,0.000000e+000,0.000000e+000,2,9.701518e-001,1.825000e+000,,,,,,,,,,,,,,,,,,0,3.000000e+000,1.000000e+000,4,4,4.149675e-004,0,,0,
1622268558.119,,-2.005631e+003,2.000167e+000,-9.011177e-003,1.843888e-006,0.000000e+000,0.000000e+000,2,9.698565e-001,1.825000e+000,,,,,,,,,,,,,,,,,,0,3.000000e+000,1.000000e+000,4,4,2.210140e-004,0,,0,
1622268641.329,,-1.003574e+003,1.999763e+000,-4.547832e-003,2.706430e-006,0.000000e+000,0.000000e+000,2,9.702117e-001,1.825000e+000,,,,,,,,,,,,,,,,,,0,3.000000e+000,1.000000e+000,4,4,6.090403e-004,0,,0,
1622268682.326,,-9.032717e+002,2.000136e+000,-4.098979e-003,1.385372e-006,0.000000e+000,0.000000e+000,2,9.702772e-001,1.825000e+000,,,,,,,,,,,,,,,,,,0,3.000000e+000,1.000000e+000,4,4,4.149675e-004,0,,0,
1622268723.760,,-8.029268e+002,2.000244e+000,-3.650720e-003,1.701000e-006,0.000000e+000,0.000000e+000,2,9.703750e-001,1.825000e+000,,,,,,,,,,,,,,,,,,0,3.000000e+000,1.000000e+000,4,4,3.330708e-004,0,,0,
1622268764.835,,-7.026241e+002,2.000266e+000,-3.203186e-003,1.259308e-006,0.000000e+000,0.000000e+000,2,9.706182e-001,1.825000e+000,,,,,,,,,,,,,,,,,,0,3.000000e+000,1.000000e+000,4,4,1.797676e-004,0,,0,
1622268806.097,,-6.021529e+002,2.000185e+000,-2.754895e-003,8.612171e-007,0.000000e+000,0.000000e+000,2,9.707633e-001,1.825000e+000,,,,,,,,,,,,,,,,,,0,3.000000e+000,1.000000e+000,4,4,2.629757e-004,0,,0,
1622268855.081,,-5.020294e+002,2.000051e+000,-2.308353e-003,2.367997e-006,0.000000e+000,0.000000e+000,2,9.710467e-001,1.825000e+000,,,,,,,,,,,,,,,,,,0,3.000000e+000,1.000000e+000,4,4,1.659393e-004,0,,0,
1622268896.655,,-4.017373e+002,1.999961e+000,-1.861101e-003,8.577652e-007,0.000000e+000,0.000000e+000,2,9.714497e-001,1.825000e+000,,,,,,,,,,,,,,,,,,0,3.000000e+000,1.000000e+000,4,4,2.899170e-004,0,,0,
1622268937.964,,-3.015085e+002,1.999898e+000,-1.414583e-003,1.830813e-006,0.000000e+000,0.000000e+000,2,9.724109e-001,1.825000e+000,,,,,,,,,,,,,,,,,,0,3.000000e+000,1.000000e+000,4,4,3.039837e-004,0,,0,
1622268978.961,,-2.010477e+002,1.999991e+000,-9.662512e-004,1.112781e-006,0.000000e+000,0.000000e+000,2,9.733851e-001,1.825000e+000,,,,,,,,,,,,,,,,,,0,3.000000e+000,1.000000e+000,4,4,2.490282e-004,0,,0,
1622269028.444,,-1.008610e+002,2.000071e+000,-5.188975e-004,4.101439e-007,0.000000e+000,0.000000e+000,2,9.763542e-001,1.825000e+000,,,,,,,,,,,,,,,,,,0,3.000000e+000,1.000000e+000,4,4,3.190041e-004,0,,0,
1622269079.019,,-3.476877e-001,2.000121e+000,-6.233191e-005,5.169650e-007,0.000000e+000,0.000000e+000,2,9.325663e-001,1.825000e+000,,,,,,,,,,,,,,,,,,0,3.000000e+000,1.000000e+000,4,4,2.360344e-004,0,,0,
1622269159.593,,-3.371517e-001,1.999879e+000,-6.072377e-005,1.613049e-007,0.000000e+000,0.000000e+000,2,9.312171e-001,1.825000e+000,,,,,,,,,,,,,,,,,,0,3.000000e+000,1.000000e+000,4,4,7.330179e-004,0,,0,
1622269209.420,,1.008716e+002,2.000187e+000,3.910514e-004,4.608234e-007,0.000000e+000,0.000000e+000,2,9.574286e-001,1.825000e+000,,,,,,,,,,,,,,,,,,0,3.000000e+000,1.000000e+000,4,4,5.120039e-004,0,,0,
1622269262.865,,2.011847e+002,2.000411e+000,8.378702e-004,1.944057e-007,0.000000e+000,0.000000e+000,2,9.638394e-001,1.825000e+000,,,,,,,,,,,,,,,,,,0,3.000000e+000,1.000000e+000,4,4,2.489090e-004,0,,0,
1622269304.658,,3.034260e+002,2.000266e+000,1.292797e-003,7.588146e-007,0.000000e+000,0.000000e+000,2,9.655089e-001,1.825000e+000,,,,,,,,,,,,,,,,,,0,3.000000e+000,1.000000e+000,4,4,9.703636e-005,0,,0,
1622269346.232,,4.066366e+002,2.000036e+000,1.756081e-003,2.287755e-006,0.000000e+000,0.000000e+000,2,9.669390e-001,1.825000e+000,,,,,,,,,,,,,,,,,,0,3.000000e+000,1.000000e+000,4,4,1.659393e-004,0,,0,
1622269413.203,,5.264203e+002,2.000037e+000,2.249383e-003,3.871288e-005,0.000000e+000,0.000000e+000,2,9.581332e-001,1.825000e+000,,,,,,,,,,,,,,,,,,0,3.000000e+000,1.000000e+000,4,4,3.319979e-004,0,,0,
1622269453.716,,6.062410e+002,1.999906e+000,2.640451e-003,1.199642e-006,0.000000e+000,0.000000e+000,2,9.675373e-001,1.825000e+000,,,,,,,,,,,,,,,,,,0,3.000000e+000,1.000000e+000,4,4,1.790524e-004,0,,0,
1622269494.760,,7.087141e+002,1.999927e+000,3.099815e-003,8.752204e-006,0.000000e+000,0.000000e+000,2,9.673843e-001,1.825000e+000,,,,,,,,,,,,,,,,,,0,3.000000e+000,1.000000e+000,4,4,3.180504e-004,0,,0,
1622269536.350,,8.069302e+002,2.000015e+000,3.532326e-003,1.354587e-006,0.000000e+000,0.000000e+000,2,9.678578e-001,1.825000e+000,,,,,,,,,,,,,,,,,,0,3.000000e+000,1.000000e+000,4,4,3.869534e-004,0,,0,
1622269601.230,,9.115740e+002,2.000128e+000,3.997986e-003,3.178733e-005,0.000000e+000,0.000000e+000,2,9.675196e-001,1.825000e+000,,,,,,,,,,,,,,,,,,0,3.000000e+000,1.000000e+000,4,4,2.770424e-004,0,,0,
1622269642.274,,1.006608e+003,2.000090e+000,4.420787e-003,4.505006e-006,0.000000e+000,0.000000e+000,2,9.676644e-001,1.825000e+000,,,,,,,,,,,,,,,,,,0,3.000000e+000,1.000000e+000,4,4,2.360344e-004,0,,0,
1622269734.220,,2.010689e+003,2.000185e+000,8.856736e-003,6.758584e-007,0.000000e+000,0.000000e+000,2,9.689409e-001,1.825000e+000,,,,,,,,,,,,,,,,,,0,3.000000e+000,1.000000e+000,4,4,6.359816e-004,0,,0,
1622269778.446,,3.015612e+003,2.000465e+000,1.326867e-002,5.064394e-007,0.000000e+000,0.000000e+000,2,9.694839e-001,1.825000e+000,,,,,,,,,,,,,,,,,,0,3.000000e+000,1.000000e+000,4,4,4.150867e-004,0,,0,
1622269822.938,,4.018005e+003,2.000387e+000,1.763679e-002,1.185502e-006,0.000000e+000,0.000000e+000,2,9.703130e-001,1.825000e+000,,,,,,,,,,,,,,,,,,0,3.000000e+000,1.000000e+000,4,4,2.081394e-004,0,,0,
1622269874.886,,5.021559e+003,2.000178e+000,2.197117e-002,1.066901e-006,0.000000e+000,0.000000e+000,2,9.710426e-001,1.825000e+000,,,,,,,,,,,,,,,,,,0,3.000000e+000,1.000000e+000,4,4,2.350807e-004,0,,0,
1622269919.112,,6.023426e+003,1.999989e+000,2.624835e-002,1.987852e-006,0.000000e+000,0.000000e+000,2,9.719675e-001,1.825000e+000,,,,,,,,,,,,,,,,,,0,3.000000e+000,1.000000e+000,4,4,3.730059e-004,0,,0,
1622269963.073,,7.033830e+003,1.999892e+000,3.049692e-002,1.377733e-005,0.000000e+000,0.000000e+000,2,9.728959e-001,1.825000e+000,,,,,,,,,,,,,,,,,,0,3.000000e+000,1.000000e+000,4,4,3.731251e-004,0,,0,
1622270008.094,,8.026949e+003,1.999948e+000,3.466093e-002,1.330010e-006,0.000000e+000,0.000000e+000,2,9.737572e-001,1.825000e+000,,,,,,,,,,,,,,,,,,0,3.000000e+000,1.000000e+000,4,4,3.460646e-004,0,,0,
1622270053.412,,9.029977e+003,2.000010e+000,3.879894e-002,2.703342e-006,0.000000e+000,0.000000e+000,2,9.746851e-001,1.825000e+000,,,,,,,,,,,,,,,,,,0,3.000000e+000,1.000000e+000,4,4,5.400181e-004,0,,0,
1622270118.277,,1.002921e+004,2.000247e+000,4.288862e-002,2.791704e-006,0.000000e+000,0.000000e+000,2,9.755315e-001,1.825000e+000,,,,,,,,,,,,,,,,,,0,3.000000e+000,1.000000e+000,4,4,8.296967e-005,0,,0,
1622270216.870,,1.503433e+004,1.999806e+000,6.272148e-002,6.396612e-006,0.000000e+000,0.000000e+000,2,9.784448e-001,1.825000e+000,,,,,,,,,,,,,,,,,,0,3.000000e+000,1.000000e+000,4,4,7.880926e-004,0,,0,
1622270275.728,,2.004683e+004,2.000148e+000,8.187307e-002,3.903284e-006,0.000000e+000,0.000000e+000,2,9.793243e-001,1.825000e+000,,,,,,,,,,,,,,,,,,0,3.000000e+000,1.000000e+000,4,4,6.499290e-004,0,,0,
1622270335.336,,2.506512e+004,2.000271e+000,1.005708e-001,1.743717e-006,0.000000e+000,0.000000e+000,2,9.788675e-001,1.825000e+000,,,,,,,,,,,,,,,,,,0,3.000000e+000,1.000000e+000,4,4,4.839897e-004,0,,0,
1622270394.679,,3.008395e+004,2.000225e+000,1.189179e-001,1.132990e-005,0.000000e+000,0.000000e+000,2,9.777938e-001,1.825000e+000,,,,,,,,,,,,,,,,,,0,3.000000e+000,1.000000e+000,4,4,5.401373e-004,0,,0,
1622270454.817,,3.508801e+004,2.000131e+000,1.369677e-001,3.252323e-005,0.000000e+000,0.000000e+000,2,9.762424e-001,1.825000e+000,,,,,,,,,,,,,,,,,,0,3.000000e+000,1.000000e+000,4,4,5.668402e-004,0,,0,
1622270514.409,,4.012000e+004,2.000062e+000,1.549107e-001,3.935965e-005,0.000000e+000,0.000000e+000,2,9.753155e-001,1.825000e+000,,,,,,,,,,,,,,,,,,0,3.000000e+000,1.000000e+000,4,4,6.090403e-004,0,,0,
1622270574.219,,4.514251e+004,2.000084e+000,1.727301e-001,4.456112e-006,0.000000e+000,0.000000e+000,2,9.741319e-001,1.825000e+000,,,,,,,,,,,,,,,,,,0,3.000000e+000,1.000000e+000,4,4,5.121231e-004,0,,0,
1622270634.467,,5.016502e+004,2.000112e+000,1.904564e-001,2.126233e-005,0.000000e+000,0.000000e+000,2,9.729762e-001,1.825000e+000,,,,,,,,,,,,,,,,,,0,3.000000e+000,1.000000e+000,4,4,6.359816e-004,0,,0,